2020-10-05 20:43:56.995156: I tensorflow/stream_executor/platform/default/dso_loader.cc:44] Successfully opened dynamic library cudart64_100.dll
Running tests under Python 3.6.12: C:\ProgramData\Anaconda3\envs\keras\python.exe
[ RUN      ] CompilationEnabledInGradientTest.testCompilationGradientScopeNames_function
2020-10-05 20:44:00.478816: I tensorflow/stream_executor/platform/default/dso_loader.cc:44] Successfully opened dynamic library nvcuda.dll
2020-10-05 20:44:00.590964: I tensorflow/core/common_runtime/gpu/gpu_device.cc:1618] Found device 0 with properties: 
name: GeForce RTX 2080 Ti major: 7 minor: 5 memoryClockRate(GHz): 1.65
pciBusID: 0000:73:00.0
2020-10-05 20:44:00.592673: I tensorflow/stream_executor/platform/default/dso_loader.cc:44] Successfully opened dynamic library cudart64_100.dll
2020-10-05 20:44:00.597007: I tensorflow/stream_executor/platform/default/dso_loader.cc:44] Successfully opened dynamic library cublas64_100.dll
2020-10-05 20:44:00.600667: I tensorflow/stream_executor/platform/default/dso_loader.cc:44] Successfully opened dynamic library cufft64_100.dll
2020-10-05 20:44:00.602340: I tensorflow/stream_executor/platform/default/dso_loader.cc:44] Successfully opened dynamic library curand64_100.dll
2020-10-05 20:44:00.606952: I tensorflow/stream_executor/platform/default/dso_loader.cc:44] Successfully opened dynamic library cusolver64_100.dll
2020-10-05 20:44:00.610117: I tensorflow/stream_executor/platform/default/dso_loader.cc:44] Successfully opened dynamic library cusparse64_100.dll
2020-10-05 20:44:00.619141: I tensorflow/stream_executor/platform/default/dso_loader.cc:44] Successfully opened dynamic library cudnn64_7.dll
2020-10-05 20:44:00.620078: I tensorflow/core/common_runtime/gpu/gpu_device.cc:1746] Adding visible gpu devices: 0
2020-10-05 20:44:00.620626: I tensorflow/core/platform/cpu_feature_guard.cc:142] Your CPU supports instructions that this TensorFlow binary was not compiled to use: AVX2
2020-10-05 20:44:00.634460: I tensorflow/core/common_runtime/gpu/gpu_device.cc:1618] Found device 0 with properties: 
name: GeForce RTX 2080 Ti major: 7 minor: 5 memoryClockRate(GHz): 1.65
pciBusID: 0000:73:00.0
2020-10-05 20:44:00.635031: I tensorflow/stream_executor/platform/default/dso_loader.cc:44] Successfully opened dynamic library cudart64_100.dll
2020-10-05 20:44:00.635403: I tensorflow/stream_executor/platform/default/dso_loader.cc:44] Successfully opened dynamic library cublas64_100.dll
2020-10-05 20:44:00.635743: I tensorflow/stream_executor/platform/default/dso_loader.cc:44] Successfully opened dynamic library cufft64_100.dll
2020-10-05 20:44:00.636081: I tensorflow/stream_executor/platform/default/dso_loader.cc:44] Successfully opened dynamic library curand64_100.dll
2020-10-05 20:44:00.636419: I tensorflow/stream_executor/platform/default/dso_loader.cc:44] Successfully opened dynamic library cusolver64_100.dll
2020-10-05 20:44:00.636759: I tensorflow/stream_executor/platform/default/dso_loader.cc:44] Successfully opened dynamic library cusparse64_100.dll
2020-10-05 20:44:00.637101: I tensorflow/stream_executor/platform/default/dso_loader.cc:44] Successfully opened dynamic library cudnn64_7.dll
2020-10-05 20:44:00.637935: I tensorflow/core/common_runtime/gpu/gpu_device.cc:1746] Adding visible gpu devices: 0
2020-10-05 20:44:01.572196: I tensorflow/core/common_runtime/gpu/gpu_device.cc:1159] Device interconnect StreamExecutor with strength 1 edge matrix:
2020-10-05 20:44:01.572613: I tensorflow/core/common_runtime/gpu/gpu_device.cc:1165]      0 
2020-10-05 20:44:01.572846: I tensorflow/core/common_runtime/gpu/gpu_device.cc:1178] 0:   N 
2020-10-05 20:44:01.573614: I tensorflow/core/common_runtime/gpu/gpu_device.cc:1304] Created TensorFlow device (/job:localhost/replica:0/task:0/device:GPU:0 with 8686 MB memory) -> physical GPU (device: 0, name: GeForce RTX 2080 Ti, pci bus id: 0000:73:00.0, compute capability: 7.5)
WARNING:tensorflow:Entity <function build_as_function_and_v1_graph.<locals>.decorator.<locals>.decorated.<locals>.function_in_eager at 0x0000017DD3337378> could not be transformed and will be executed as-is. Please report this to the AutoGraph team. When filing the bug, set the verbosity to 10 (on Linux, `export AUTOGRAPH_VERBOSITY=10`) and attach the full output. Cause: 'NoneType' object has no attribute '_fields'
W1005 20:44:02.767392 18708 ag_logging.py:146] Entity <function build_as_function_and_v1_graph.<locals>.decorator.<locals>.decorated.<locals>.function_in_eager at 0x0000017DD3337378> could not be transformed and will be executed as-is. Please report this to the AutoGraph team. When filing the bug, set the verbosity to 10 (on Linux, `export AUTOGRAPH_VERBOSITY=10`) and attach the full output. Cause: 'NoneType' object has no attribute '_fields'
2020-10-05 20:44:02.774068: I tensorflow/core/common_runtime/gpu/gpu_device.cc:1618] Found device 0 with properties: 
name: GeForce RTX 2080 Ti major: 7 minor: 5 memoryClockRate(GHz): 1.65
pciBusID: 0000:73:00.0
2020-10-05 20:44:02.774631: I tensorflow/stream_executor/platform/default/dso_loader.cc:44] Successfully opened dynamic library cudart64_100.dll
2020-10-05 20:44:02.775045: I tensorflow/stream_executor/platform/default/dso_loader.cc:44] Successfully opened dynamic library cublas64_100.dll
2020-10-05 20:44:02.775518: I tensorflow/stream_executor/platform/default/dso_loader.cc:44] Successfully opened dynamic library cufft64_100.dll
2020-10-05 20:44:02.775950: I tensorflow/stream_executor/platform/default/dso_loader.cc:44] Successfully opened dynamic library curand64_100.dll
2020-10-05 20:44:02.776354: I tensorflow/stream_executor/platform/default/dso_loader.cc:44] Successfully opened dynamic library cusolver64_100.dll
2020-10-05 20:44:02.776818: I tensorflow/stream_executor/platform/default/dso_loader.cc:44] Successfully opened dynamic library cusparse64_100.dll
2020-10-05 20:44:02.777259: I tensorflow/stream_executor/platform/default/dso_loader.cc:44] Successfully opened dynamic library cudnn64_7.dll
2020-10-05 20:44:02.777921: I tensorflow/core/common_runtime/gpu/gpu_device.cc:1746] Adding visible gpu devices: 0
2020-10-05 20:44:02.778243: I tensorflow/core/common_runtime/gpu/gpu_device.cc:1159] Device interconnect StreamExecutor with strength 1 edge matrix:
2020-10-05 20:44:02.778600: I tensorflow/core/common_runtime/gpu/gpu_device.cc:1165]      0 
2020-10-05 20:44:02.778826: I tensorflow/core/common_runtime/gpu/gpu_device.cc:1178] 0:   N 
2020-10-05 20:44:02.779314: I tensorflow/core/common_runtime/gpu/gpu_device.cc:1304] Created TensorFlow device (/job:localhost/replica:0/task:0/device:GPU:0 with 8686 MB memory) -> physical GPU (device: 0, name: GeForce RTX 2080 Ti, pci bus id: 0000:73:00.0, compute capability: 7.5)
[  FAILED  ] CompilationEnabledInGradientTest.testCompilationGradientScopeNames_function
[ RUN      ] CompilationEnabledInGradientTest.testCompilationGradientScopeNames_v1_graph
2020-10-05 20:44:02.814552: I tensorflow/core/common_runtime/gpu/gpu_device.cc:1618] Found device 0 with properties: 
name: GeForce RTX 2080 Ti major: 7 minor: 5 memoryClockRate(GHz): 1.65
pciBusID: 0000:73:00.0
2020-10-05 20:44:02.815816: I tensorflow/stream_executor/platform/default/dso_loader.cc:44] Successfully opened dynamic library cudart64_100.dll
2020-10-05 20:44:02.816666: I tensorflow/stream_executor/platform/default/dso_loader.cc:44] Successfully opened dynamic library cublas64_100.dll
2020-10-05 20:44:02.817521: I tensorflow/stream_executor/platform/default/dso_loader.cc:44] Successfully opened dynamic library cufft64_100.dll
2020-10-05 20:44:02.818362: I tensorflow/stream_executor/platform/default/dso_loader.cc:44] Successfully opened dynamic library curand64_100.dll
2020-10-05 20:44:02.819214: I tensorflow/stream_executor/platform/default/dso_loader.cc:44] Successfully opened dynamic library cusolver64_100.dll
2020-10-05 20:44:02.820073: I tensorflow/stream_executor/platform/default/dso_loader.cc:44] Successfully opened dynamic library cusparse64_100.dll
2020-10-05 20:44:02.820938: I tensorflow/stream_executor/platform/default/dso_loader.cc:44] Successfully opened dynamic library cudnn64_7.dll
2020-10-05 20:44:02.822005: I tensorflow/core/common_runtime/gpu/gpu_device.cc:1746] Adding visible gpu devices: 0
2020-10-05 20:44:02.822496: I tensorflow/core/common_runtime/gpu/gpu_device.cc:1159] Device interconnect StreamExecutor with strength 1 edge matrix:
2020-10-05 20:44:02.822992: I tensorflow/core/common_runtime/gpu/gpu_device.cc:1165]      0 
2020-10-05 20:44:02.823302: I tensorflow/core/common_runtime/gpu/gpu_device.cc:1178] 0:   N 
2020-10-05 20:44:02.824006: I tensorflow/core/common_runtime/gpu/gpu_device.cc:1304] Created TensorFlow device (/job:localhost/replica:0/task:0/device:GPU:0 with 8686 MB memory) -> physical GPU (device: 0, name: GeForce RTX 2080 Ti, pci bus id: 0000:73:00.0, compute capability: 7.5)
[  FAILED  ] CompilationEnabledInGradientTest.testCompilationGradientScopeNames_v1_graph
[ RUN      ] CompilationEnabledInGradientTest.testCompilationInGradient_function
WARNING:tensorflow:Entity <function build_as_function_and_v1_graph.<locals>.decorator.<locals>.decorated.<locals>.function_in_eager at 0x0000017DD33372F0> could not be transformed and will be executed as-is. Please report this to the AutoGraph team. When filing the bug, set the verbosity to 10 (on Linux, `export AUTOGRAPH_VERBOSITY=10`) and attach the full output. Cause: 'NoneType' object has no attribute '_fields'
W1005 20:44:02.845498 18708 ag_logging.py:146] Entity <function build_as_function_and_v1_graph.<locals>.decorator.<locals>.decorated.<locals>.function_in_eager at 0x0000017DD33372F0> could not be transformed and will be executed as-is. Please report this to the AutoGraph team. When filing the bug, set the verbosity to 10 (on Linux, `export AUTOGRAPH_VERBOSITY=10`) and attach the full output. Cause: 'NoneType' object has no attribute '_fields'
2020-10-05 20:44:02.855809: I tensorflow/core/common_runtime/gpu/gpu_device.cc:1618] Found device 0 with properties: 
name: GeForce RTX 2080 Ti major: 7 minor: 5 memoryClockRate(GHz): 1.65
pciBusID: 0000:73:00.0
2020-10-05 20:44:02.856322: I tensorflow/stream_executor/platform/default/dso_loader.cc:44] Successfully opened dynamic library cudart64_100.dll
2020-10-05 20:44:02.856672: I tensorflow/stream_executor/platform/default/dso_loader.cc:44] Successfully opened dynamic library cublas64_100.dll
2020-10-05 20:44:02.857011: I tensorflow/stream_executor/platform/default/dso_loader.cc:44] Successfully opened dynamic library cufft64_100.dll
2020-10-05 20:44:02.857349: I tensorflow/stream_executor/platform/default/dso_loader.cc:44] Successfully opened dynamic library curand64_100.dll
2020-10-05 20:44:02.857721: I tensorflow/stream_executor/platform/default/dso_loader.cc:44] Successfully opened dynamic library cusolver64_100.dll
2020-10-05 20:44:02.858062: I tensorflow/stream_executor/platform/default/dso_loader.cc:44] Successfully opened dynamic library cusparse64_100.dll
2020-10-05 20:44:02.858404: I tensorflow/stream_executor/platform/default/dso_loader.cc:44] Successfully opened dynamic library cudnn64_7.dll
2020-10-05 20:44:02.858954: I tensorflow/core/common_runtime/gpu/gpu_device.cc:1746] Adding visible gpu devices: 0
2020-10-05 20:44:02.859261: I tensorflow/core/common_runtime/gpu/gpu_device.cc:1159] Device interconnect StreamExecutor with strength 1 edge matrix:
2020-10-05 20:44:02.859618: I tensorflow/core/common_runtime/gpu/gpu_device.cc:1165]      0 
2020-10-05 20:44:02.859837: I tensorflow/core/common_runtime/gpu/gpu_device.cc:1178] 0:   N 
2020-10-05 20:44:02.860314: I tensorflow/core/common_runtime/gpu/gpu_device.cc:1304] Created TensorFlow device (/job:localhost/replica:0/task:0/device:GPU:0 with 8686 MB memory) -> physical GPU (device: 0, name: GeForce RTX 2080 Ti, pci bus id: 0000:73:00.0, compute capability: 7.5)
[  FAILED  ] CompilationEnabledInGradientTest.testCompilationInGradient_function
[ RUN      ] CompilationEnabledInGradientTest.testCompilationInGradient_v1_graph
2020-10-05 20:44:02.864302: I tensorflow/core/common_runtime/gpu/gpu_device.cc:1618] Found device 0 with properties: 
name: GeForce RTX 2080 Ti major: 7 minor: 5 memoryClockRate(GHz): 1.65
pciBusID: 0000:73:00.0
2020-10-05 20:44:02.864814: I tensorflow/stream_executor/platform/default/dso_loader.cc:44] Successfully opened dynamic library cudart64_100.dll
2020-10-05 20:44:02.865160: I tensorflow/stream_executor/platform/default/dso_loader.cc:44] Successfully opened dynamic library cublas64_100.dll
2020-10-05 20:44:02.865501: I tensorflow/stream_executor/platform/default/dso_loader.cc:44] Successfully opened dynamic library cufft64_100.dll
2020-10-05 20:44:02.865848: I tensorflow/stream_executor/platform/default/dso_loader.cc:44] Successfully opened dynamic library curand64_100.dll
2020-10-05 20:44:02.866188: I tensorflow/stream_executor/platform/default/dso_loader.cc:44] Successfully opened dynamic library cusolver64_100.dll
2020-10-05 20:44:02.866533: I tensorflow/stream_executor/platform/default/dso_loader.cc:44] Successfully opened dynamic library cusparse64_100.dll
2020-10-05 20:44:02.866877: I tensorflow/stream_executor/platform/default/dso_loader.cc:44] Successfully opened dynamic library cudnn64_7.dll
2020-10-05 20:44:02.867427: I tensorflow/core/common_runtime/gpu/gpu_device.cc:1746] Adding visible gpu devices: 0
2020-10-05 20:44:02.867727: I tensorflow/core/common_runtime/gpu/gpu_device.cc:1159] Device interconnect StreamExecutor with strength 1 edge matrix:
2020-10-05 20:44:02.868073: I tensorflow/core/common_runtime/gpu/gpu_device.cc:1165]      0 
2020-10-05 20:44:02.868290: I tensorflow/core/common_runtime/gpu/gpu_device.cc:1178] 0:   N 
2020-10-05 20:44:02.868770: I tensorflow/core/common_runtime/gpu/gpu_device.cc:1304] Created TensorFlow device (/job:localhost/replica:0/task:0/device:GPU:0 with 8686 MB memory) -> physical GPU (device: 0, name: GeForce RTX 2080 Ti, pci bus id: 0000:73:00.0, compute capability: 7.5)
[  FAILED  ] CompilationEnabledInGradientTest.testCompilationInGradient_v1_graph
[ RUN      ] CompilationEnabledInGradientTest.testCompilationSeparateGradientScopeNames_function
WARNING:tensorflow:Entity <function build_as_function_and_v1_graph.<locals>.decorator.<locals>.decorated.<locals>.function_in_eager at 0x0000017DD3337400> could not be transformed and will be executed as-is. Please report this to the AutoGraph team. When filing the bug, set the verbosity to 10 (on Linux, `export AUTOGRAPH_VERBOSITY=10`) and attach the full output. Cause: 'NoneType' object has no attribute '_fields'
W1005 20:44:02.892363 18708 ag_logging.py:146] Entity <function build_as_function_and_v1_graph.<locals>.decorator.<locals>.decorated.<locals>.function_in_eager at 0x0000017DD3337400> could not be transformed and will be executed as-is. Please report this to the AutoGraph team. When filing the bug, set the verbosity to 10 (on Linux, `export AUTOGRAPH_VERBOSITY=10`) and attach the full output. Cause: 'NoneType' object has no attribute '_fields'
2020-10-05 20:44:02.898911: I tensorflow/core/common_runtime/gpu/gpu_device.cc:1618] Found device 0 with properties: 
name: GeForce RTX 2080 Ti major: 7 minor: 5 memoryClockRate(GHz): 1.65
pciBusID: 0000:73:00.0
2020-10-05 20:44:02.899427: I tensorflow/stream_executor/platform/default/dso_loader.cc:44] Successfully opened dynamic library cudart64_100.dll
2020-10-05 20:44:02.899769: I tensorflow/stream_executor/platform/default/dso_loader.cc:44] Successfully opened dynamic library cublas64_100.dll
2020-10-05 20:44:02.900113: I tensorflow/stream_executor/platform/default/dso_loader.cc:44] Successfully opened dynamic library cufft64_100.dll
2020-10-05 20:44:02.900452: I tensorflow/stream_executor/platform/default/dso_loader.cc:44] Successfully opened dynamic library curand64_100.dll
2020-10-05 20:44:02.900801: I tensorflow/stream_executor/platform/default/dso_loader.cc:44] Successfully opened dynamic library cusolver64_100.dll
2020-10-05 20:44:02.901145: I tensorflow/stream_executor/platform/default/dso_loader.cc:44] Successfully opened dynamic library cusparse64_100.dll
2020-10-05 20:44:02.901493: I tensorflow/stream_executor/platform/default/dso_loader.cc:44] Successfully opened dynamic library cudnn64_7.dll
2020-10-05 20:44:02.902043: I tensorflow/core/common_runtime/gpu/gpu_device.cc:1746] Adding visible gpu devices: 0
2020-10-05 20:44:02.902394: I tensorflow/core/common_runtime/gpu/gpu_device.cc:1159] Device interconnect StreamExecutor with strength 1 edge matrix:
2020-10-05 20:44:02.902742: I tensorflow/core/common_runtime/gpu/gpu_device.cc:1165]      0 
2020-10-05 20:44:02.902959: I tensorflow/core/common_runtime/gpu/gpu_device.cc:1178] 0:   N 
2020-10-05 20:44:02.903437: I tensorflow/core/common_runtime/gpu/gpu_device.cc:1304] Created TensorFlow device (/job:localhost/replica:0/task:0/device:GPU:0 with 8686 MB memory) -> physical GPU (device: 0, name: GeForce RTX 2080 Ti, pci bus id: 0000:73:00.0, compute capability: 7.5)
[  FAILED  ] CompilationEnabledInGradientTest.testCompilationSeparateGradientScopeNames_function
[ RUN      ] CompilationEnabledInGradientTest.testCompilationSeparateGradientScopeNames_v1_graph
2020-10-05 20:44:02.906806: I tensorflow/core/common_runtime/gpu/gpu_device.cc:1618] Found device 0 with properties: 
name: GeForce RTX 2080 Ti major: 7 minor: 5 memoryClockRate(GHz): 1.65
pciBusID: 0000:73:00.0
2020-10-05 20:44:02.907324: I tensorflow/stream_executor/platform/default/dso_loader.cc:44] Successfully opened dynamic library cudart64_100.dll
2020-10-05 20:44:02.907667: I tensorflow/stream_executor/platform/default/dso_loader.cc:44] Successfully opened dynamic library cublas64_100.dll
2020-10-05 20:44:02.908011: I tensorflow/stream_executor/platform/default/dso_loader.cc:44] Successfully opened dynamic library cufft64_100.dll
2020-10-05 20:44:02.908407: I tensorflow/stream_executor/platform/default/dso_loader.cc:44] Successfully opened dynamic library curand64_100.dll
2020-10-05 20:44:02.908769: I tensorflow/stream_executor/platform/default/dso_loader.cc:44] Successfully opened dynamic library cusolver64_100.dll
2020-10-05 20:44:02.909136: I tensorflow/stream_executor/platform/default/dso_loader.cc:44] Successfully opened dynamic library cusparse64_100.dll
2020-10-05 20:44:02.909503: I tensorflow/stream_executor/platform/default/dso_loader.cc:44] Successfully opened dynamic library cudnn64_7.dll
2020-10-05 20:44:02.910070: I tensorflow/core/common_runtime/gpu/gpu_device.cc:1746] Adding visible gpu devices: 0
2020-10-05 20:44:02.910369: I tensorflow/core/common_runtime/gpu/gpu_device.cc:1159] Device interconnect StreamExecutor with strength 1 edge matrix:
2020-10-05 20:44:02.910717: I tensorflow/core/common_runtime/gpu/gpu_device.cc:1165]      0 
2020-10-05 20:44:02.910935: I tensorflow/core/common_runtime/gpu/gpu_device.cc:1178] 0:   N 
2020-10-05 20:44:02.911401: I tensorflow/core/common_runtime/gpu/gpu_device.cc:1304] Created TensorFlow device (/job:localhost/replica:0/task:0/device:GPU:0 with 8686 MB memory) -> physical GPU (device: 0, name: GeForce RTX 2080 Ti, pci bus id: 0000:73:00.0, compute capability: 7.5)
[  FAILED  ] CompilationEnabledInGradientTest.testCompilationSeparateGradientScopeNames_v1_graph
[ RUN      ] CompilationEnabledInGradientTest.testPlaysNicelyWithDefunSeparateGradientScope_function
WARNING:tensorflow:Entity <function build_as_function_and_v1_graph.<locals>.decorator.<locals>.decorated.<locals>.function_in_eager at 0x0000017D891F2F28> could not be transformed and will be executed as-is. Please report this to the AutoGraph team. When filing the bug, set the verbosity to 10 (on Linux, `export AUTOGRAPH_VERBOSITY=10`) and attach the full output. Cause: 'NoneType' object has no attribute '_fields'
W1005 20:44:02.939231 18708 ag_logging.py:146] Entity <function build_as_function_and_v1_graph.<locals>.decorator.<locals>.decorated.<locals>.function_in_eager at 0x0000017D891F2F28> could not be transformed and will be executed as-is. Please report this to the AutoGraph team. When filing the bug, set the verbosity to 10 (on Linux, `export AUTOGRAPH_VERBOSITY=10`) and attach the full output. Cause: 'NoneType' object has no attribute '_fields'
2020-10-05 20:44:02.941024: I tensorflow/core/common_runtime/gpu/gpu_device.cc:1618] Found device 0 with properties: 
name: GeForce RTX 2080 Ti major: 7 minor: 5 memoryClockRate(GHz): 1.65
pciBusID: 0000:73:00.0
2020-10-05 20:44:02.941534: I tensorflow/stream_executor/platform/default/dso_loader.cc:44] Successfully opened dynamic library cudart64_100.dll
2020-10-05 20:44:02.941951: I tensorflow/stream_executor/platform/default/dso_loader.cc:44] Successfully opened dynamic library cublas64_100.dll
2020-10-05 20:44:02.942320: I tensorflow/stream_executor/platform/default/dso_loader.cc:44] Successfully opened dynamic library cufft64_100.dll
2020-10-05 20:44:02.942685: I tensorflow/stream_executor/platform/default/dso_loader.cc:44] Successfully opened dynamic library curand64_100.dll
2020-10-05 20:44:02.943057: I tensorflow/stream_executor/platform/default/dso_loader.cc:44] Successfully opened dynamic library cusolver64_100.dll
2020-10-05 20:44:02.943401: I tensorflow/stream_executor/platform/default/dso_loader.cc:44] Successfully opened dynamic library cusparse64_100.dll
2020-10-05 20:44:02.943745: I tensorflow/stream_executor/platform/default/dso_loader.cc:44] Successfully opened dynamic library cudnn64_7.dll
2020-10-05 20:44:02.944304: I tensorflow/core/common_runtime/gpu/gpu_device.cc:1746] Adding visible gpu devices: 0
2020-10-05 20:44:02.944603: I tensorflow/core/common_runtime/gpu/gpu_device.cc:1159] Device interconnect StreamExecutor with strength 1 edge matrix:
2020-10-05 20:44:02.944959: I tensorflow/core/common_runtime/gpu/gpu_device.cc:1165]      0 
2020-10-05 20:44:02.945176: I tensorflow/core/common_runtime/gpu/gpu_device.cc:1178] 0:   N 
2020-10-05 20:44:02.945667: I tensorflow/core/common_runtime/gpu/gpu_device.cc:1304] Created TensorFlow device (/job:localhost/replica:0/task:0/device:GPU:0 with 8686 MB memory) -> physical GPU (device: 0, name: GeForce RTX 2080 Ti, pci bus id: 0000:73:00.0, compute capability: 7.5)
[  FAILED  ] CompilationEnabledInGradientTest.testPlaysNicelyWithDefunSeparateGradientScope_function
[ RUN      ] CompilationEnabledInGradientTest.testPlaysNicelyWithDefunSeparateGradientScope_v1_graph
2020-10-05 20:44:02.948955: I tensorflow/core/common_runtime/gpu/gpu_device.cc:1618] Found device 0 with properties: 
name: GeForce RTX 2080 Ti major: 7 minor: 5 memoryClockRate(GHz): 1.65
pciBusID: 0000:73:00.0
2020-10-05 20:44:02.949464: I tensorflow/stream_executor/platform/default/dso_loader.cc:44] Successfully opened dynamic library cudart64_100.dll
2020-10-05 20:44:02.949805: I tensorflow/stream_executor/platform/default/dso_loader.cc:44] Successfully opened dynamic library cublas64_100.dll
2020-10-05 20:44:02.950144: I tensorflow/stream_executor/platform/default/dso_loader.cc:44] Successfully opened dynamic library cufft64_100.dll
2020-10-05 20:44:02.950489: I tensorflow/stream_executor/platform/default/dso_loader.cc:44] Successfully opened dynamic library curand64_100.dll
2020-10-05 20:44:02.950828: I tensorflow/stream_executor/platform/default/dso_loader.cc:44] Successfully opened dynamic library cusolver64_100.dll
2020-10-05 20:44:02.951174: I tensorflow/stream_executor/platform/default/dso_loader.cc:44] Successfully opened dynamic library cusparse64_100.dll
2020-10-05 20:44:02.951518: I tensorflow/stream_executor/platform/default/dso_loader.cc:44] Successfully opened dynamic library cudnn64_7.dll
2020-10-05 20:44:02.952066: I tensorflow/core/common_runtime/gpu/gpu_device.cc:1746] Adding visible gpu devices: 0
2020-10-05 20:44:02.952361: I tensorflow/core/common_runtime/gpu/gpu_device.cc:1159] Device interconnect StreamExecutor with strength 1 edge matrix:
2020-10-05 20:44:02.952707: I tensorflow/core/common_runtime/gpu/gpu_device.cc:1165]      0 
2020-10-05 20:44:02.952924: I tensorflow/core/common_runtime/gpu/gpu_device.cc:1178] 0:   N 
2020-10-05 20:44:02.953387: I tensorflow/core/common_runtime/gpu/gpu_device.cc:1304] Created TensorFlow device (/job:localhost/replica:0/task:0/device:GPU:0 with 8686 MB memory) -> physical GPU (device: 0, name: GeForce RTX 2080 Ti, pci bus id: 0000:73:00.0, compute capability: 7.5)
[  FAILED  ] CompilationEnabledInGradientTest.testPlaysNicelyWithDefunSeparateGradientScope_v1_graph
[ RUN      ] CompilationEnabledInGradientTest.testPlaysNicelyWithDefun_function
WARNING:tensorflow:Entity <function build_as_function_and_v1_graph.<locals>.decorator.<locals>.decorated.<locals>.function_in_eager at 0x0000017D89291378> could not be transformed and will be executed as-is. Please report this to the AutoGraph team. When filing the bug, set the verbosity to 10 (on Linux, `export AUTOGRAPH_VERBOSITY=10`) and attach the full output. Cause: 'NoneType' object has no attribute '_fields'
W1005 20:44:02.970476 18708 ag_logging.py:146] Entity <function build_as_function_and_v1_graph.<locals>.decorator.<locals>.decorated.<locals>.function_in_eager at 0x0000017D89291378> could not be transformed and will be executed as-is. Please report this to the AutoGraph team. When filing the bug, set the verbosity to 10 (on Linux, `export AUTOGRAPH_VERBOSITY=10`) and attach the full output. Cause: 'NoneType' object has no attribute '_fields'
2020-10-05 20:44:02.982717: I tensorflow/core/common_runtime/gpu/gpu_device.cc:1618] Found device 0 with properties: 
name: GeForce RTX 2080 Ti major: 7 minor: 5 memoryClockRate(GHz): 1.65
pciBusID: 0000:73:00.0
2020-10-05 20:44:02.983227: I tensorflow/stream_executor/platform/default/dso_loader.cc:44] Successfully opened dynamic library cudart64_100.dll
2020-10-05 20:44:02.983569: I tensorflow/stream_executor/platform/default/dso_loader.cc:44] Successfully opened dynamic library cublas64_100.dll
2020-10-05 20:44:02.983911: I tensorflow/stream_executor/platform/default/dso_loader.cc:44] Successfully opened dynamic library cufft64_100.dll
2020-10-05 20:44:02.984250: I tensorflow/stream_executor/platform/default/dso_loader.cc:44] Successfully opened dynamic library curand64_100.dll
2020-10-05 20:44:02.984589: I tensorflow/stream_executor/platform/default/dso_loader.cc:44] Successfully opened dynamic library cusolver64_100.dll
2020-10-05 20:44:02.984933: I tensorflow/stream_executor/platform/default/dso_loader.cc:44] Successfully opened dynamic library cusparse64_100.dll
2020-10-05 20:44:02.985288: I tensorflow/stream_executor/platform/default/dso_loader.cc:44] Successfully opened dynamic library cudnn64_7.dll
2020-10-05 20:44:02.985838: I tensorflow/core/common_runtime/gpu/gpu_device.cc:1746] Adding visible gpu devices: 0
2020-10-05 20:44:02.986190: I tensorflow/core/common_runtime/gpu/gpu_device.cc:1159] Device interconnect StreamExecutor with strength 1 edge matrix:
2020-10-05 20:44:02.986556: I tensorflow/core/common_runtime/gpu/gpu_device.cc:1165]      0 
2020-10-05 20:44:02.986772: I tensorflow/core/common_runtime/gpu/gpu_device.cc:1178] 0:   N 
2020-10-05 20:44:02.987240: I tensorflow/core/common_runtime/gpu/gpu_device.cc:1304] Created TensorFlow device (/job:localhost/replica:0/task:0/device:GPU:0 with 8686 MB memory) -> physical GPU (device: 0, name: GeForce RTX 2080 Ti, pci bus id: 0000:73:00.0, compute capability: 7.5)
[  FAILED  ] CompilationEnabledInGradientTest.testPlaysNicelyWithDefun_function
[ RUN      ] CompilationEnabledInGradientTest.testPlaysNicelyWithDefun_v1_graph
2020-10-05 20:44:02.994238: I tensorflow/core/common_runtime/gpu/gpu_device.cc:1618] Found device 0 with properties: 
name: GeForce RTX 2080 Ti major: 7 minor: 5 memoryClockRate(GHz): 1.65
pciBusID: 0000:73:00.0
2020-10-05 20:44:02.996146: I tensorflow/stream_executor/platform/default/dso_loader.cc:44] Successfully opened dynamic library cudart64_100.dll
2020-10-05 20:44:02.997432: I tensorflow/stream_executor/platform/default/dso_loader.cc:44] Successfully opened dynamic library cublas64_100.dll
2020-10-05 20:44:02.998716: I tensorflow/stream_executor/platform/default/dso_loader.cc:44] Successfully opened dynamic library cufft64_100.dll
2020-10-05 20:44:02.999990: I tensorflow/stream_executor/platform/default/dso_loader.cc:44] Successfully opened dynamic library curand64_100.dll
2020-10-05 20:44:03.001269: I tensorflow/stream_executor/platform/default/dso_loader.cc:44] Successfully opened dynamic library cusolver64_100.dll
2020-10-05 20:44:03.002674: I tensorflow/stream_executor/platform/default/dso_loader.cc:44] Successfully opened dynamic library cusparse64_100.dll
2020-10-05 20:44:03.003975: I tensorflow/stream_executor/platform/default/dso_loader.cc:44] Successfully opened dynamic library cudnn64_7.dll
2020-10-05 20:44:03.006054: I tensorflow/core/common_runtime/gpu/gpu_device.cc:1746] Adding visible gpu devices: 0
2020-10-05 20:44:03.007172: I tensorflow/core/common_runtime/gpu/gpu_device.cc:1159] Device interconnect StreamExecutor with strength 1 edge matrix:
2020-10-05 20:44:03.008484: I tensorflow/core/common_runtime/gpu/gpu_device.cc:1165]      0 
2020-10-05 20:44:03.009305: I tensorflow/core/common_runtime/gpu/gpu_device.cc:1178] 0:   N 
2020-10-05 20:44:03.010899: I tensorflow/core/common_runtime/gpu/gpu_device.cc:1304] Created TensorFlow device (/job:localhost/replica:0/task:0/device:GPU:0 with 8686 MB memory) -> physical GPU (device: 0, name: GeForce RTX 2080 Ti, pci bus id: 0000:73:00.0, compute capability: 7.5)
[  FAILED  ] CompilationEnabledInGradientTest.testPlaysNicelyWithDefun_v1_graph
[ RUN      ] CompilationEnabledInGradientTest.test_session
[  SKIPPED ] CompilationEnabledInGradientTest.test_session
[ RUN      ] JITTest.testDefunInheritsJitScope_function
WARNING:tensorflow:Entity <function build_as_function_and_v1_graph.<locals>.decorator.<locals>.decorated.<locals>.function_in_eager at 0x0000017D89291378> could not be transformed and will be executed as-is. Please report this to the AutoGraph team. When filing the bug, set the verbosity to 10 (on Linux, `export AUTOGRAPH_VERBOSITY=10`) and attach the full output. Cause: 'NoneType' object has no attribute '_fields'
W1005 20:44:03.048583 18708 ag_logging.py:146] Entity <function build_as_function_and_v1_graph.<locals>.decorator.<locals>.decorated.<locals>.function_in_eager at 0x0000017D89291378> could not be transformed and will be executed as-is. Please report this to the AutoGraph team. When filing the bug, set the verbosity to 10 (on Linux, `export AUTOGRAPH_VERBOSITY=10`) and attach the full output. Cause: 'NoneType' object has no attribute '_fields'
2020-10-05 20:44:03.052235: I tensorflow/core/common_runtime/gpu/gpu_device.cc:1618] Found device 0 with properties: 
name: GeForce RTX 2080 Ti major: 7 minor: 5 memoryClockRate(GHz): 1.65
pciBusID: 0000:73:00.0
2020-10-05 20:44:03.052813: I tensorflow/stream_executor/platform/default/dso_loader.cc:44] Successfully opened dynamic library cudart64_100.dll
2020-10-05 20:44:03.053181: I tensorflow/stream_executor/platform/default/dso_loader.cc:44] Successfully opened dynamic library cublas64_100.dll
2020-10-05 20:44:03.053549: I tensorflow/stream_executor/platform/default/dso_loader.cc:44] Successfully opened dynamic library cufft64_100.dll
2020-10-05 20:44:03.053914: I tensorflow/stream_executor/platform/default/dso_loader.cc:44] Successfully opened dynamic library curand64_100.dll
2020-10-05 20:44:03.054284: I tensorflow/stream_executor/platform/default/dso_loader.cc:44] Successfully opened dynamic library cusolver64_100.dll
2020-10-05 20:44:03.054659: I tensorflow/stream_executor/platform/default/dso_loader.cc:44] Successfully opened dynamic library cusparse64_100.dll
2020-10-05 20:44:03.055041: I tensorflow/stream_executor/platform/default/dso_loader.cc:44] Successfully opened dynamic library cudnn64_7.dll
2020-10-05 20:44:03.055633: I tensorflow/core/common_runtime/gpu/gpu_device.cc:1746] Adding visible gpu devices: 0
2020-10-05 20:44:03.055960: I tensorflow/core/common_runtime/gpu/gpu_device.cc:1159] Device interconnect StreamExecutor with strength 1 edge matrix:
2020-10-05 20:44:03.056336: I tensorflow/core/common_runtime/gpu/gpu_device.cc:1165]      0 
2020-10-05 20:44:03.056571: I tensorflow/core/common_runtime/gpu/gpu_device.cc:1178] 0:   N 
2020-10-05 20:44:03.057073: I tensorflow/core/common_runtime/gpu/gpu_device.cc:1304] Created TensorFlow device (/job:localhost/replica:0/task:0/device:GPU:0 with 8686 MB memory) -> physical GPU (device: 0, name: GeForce RTX 2080 Ti, pci bus id: 0000:73:00.0, compute capability: 7.5)
[  FAILED  ] JITTest.testDefunInheritsJitScope_function
[ RUN      ] JITTest.testDefunInheritsJitScope_v1_graph
2020-10-05 20:44:03.062510: I tensorflow/core/common_runtime/gpu/gpu_device.cc:1618] Found device 0 with properties: 
name: GeForce RTX 2080 Ti major: 7 minor: 5 memoryClockRate(GHz): 1.65
pciBusID: 0000:73:00.0
2020-10-05 20:44:03.064399: I tensorflow/stream_executor/platform/default/dso_loader.cc:44] Successfully opened dynamic library cudart64_100.dll
2020-10-05 20:44:03.065536: I tensorflow/stream_executor/platform/default/dso_loader.cc:44] Successfully opened dynamic library cublas64_100.dll
2020-10-05 20:44:03.066666: I tensorflow/stream_executor/platform/default/dso_loader.cc:44] Successfully opened dynamic library cufft64_100.dll
2020-10-05 20:44:03.067785: I tensorflow/stream_executor/platform/default/dso_loader.cc:44] Successfully opened dynamic library curand64_100.dll
2020-10-05 20:44:03.068916: I tensorflow/stream_executor/platform/default/dso_loader.cc:44] Successfully opened dynamic library cusolver64_100.dll
2020-10-05 20:44:03.070059: I tensorflow/stream_executor/platform/default/dso_loader.cc:44] Successfully opened dynamic library cusparse64_100.dll
2020-10-05 20:44:03.071216: I tensorflow/stream_executor/platform/default/dso_loader.cc:44] Successfully opened dynamic library cudnn64_7.dll
2020-10-05 20:44:03.072925: I tensorflow/core/common_runtime/gpu/gpu_device.cc:1746] Adding visible gpu devices: 0
2020-10-05 20:44:03.073806: I tensorflow/core/common_runtime/gpu/gpu_device.cc:1159] Device interconnect StreamExecutor with strength 1 edge matrix:
2020-10-05 20:44:03.074844: I tensorflow/core/common_runtime/gpu/gpu_device.cc:1165]      0 
2020-10-05 20:44:03.075492: I tensorflow/core/common_runtime/gpu/gpu_device.cc:1178] 0:   N 
2020-10-05 20:44:03.076775: I tensorflow/core/common_runtime/gpu/gpu_device.cc:1304] Created TensorFlow device (/job:localhost/replica:0/task:0/device:GPU:0 with 8686 MB memory) -> physical GPU (device: 0, name: GeForce RTX 2080 Ti, pci bus id: 0000:73:00.0, compute capability: 7.5)
[  FAILED  ] JITTest.testDefunInheritsJitScope_v1_graph
[ RUN      ] JITTest.testDefunNoJitScope_function
WARNING:tensorflow:Entity <function build_as_function_and_v1_graph.<locals>.decorator.<locals>.decorated.<locals>.function_in_eager at 0x0000017D891F2F28> could not be transformed and will be executed as-is. Please report this to the AutoGraph team. When filing the bug, set the verbosity to 10 (on Linux, `export AUTOGRAPH_VERBOSITY=10`) and attach the full output. Cause: 'NoneType' object has no attribute '_fields'
W1005 20:44:03.111072 18708 ag_logging.py:146] Entity <function build_as_function_and_v1_graph.<locals>.decorator.<locals>.decorated.<locals>.function_in_eager at 0x0000017D891F2F28> could not be transformed and will be executed as-is. Please report this to the AutoGraph team. When filing the bug, set the verbosity to 10 (on Linux, `export AUTOGRAPH_VERBOSITY=10`) and attach the full output. Cause: 'NoneType' object has no attribute '_fields'
2020-10-05 20:44:03.115347: I tensorflow/core/common_runtime/gpu/gpu_device.cc:1618] Found device 0 with properties: 
name: GeForce RTX 2080 Ti major: 7 minor: 5 memoryClockRate(GHz): 1.65
pciBusID: 0000:73:00.0
2020-10-05 20:44:03.115862: I tensorflow/stream_executor/platform/default/dso_loader.cc:44] Successfully opened dynamic library cudart64_100.dll
2020-10-05 20:44:03.116206: I tensorflow/stream_executor/platform/default/dso_loader.cc:44] Successfully opened dynamic library cublas64_100.dll
2020-10-05 20:44:03.116549: I tensorflow/stream_executor/platform/default/dso_loader.cc:44] Successfully opened dynamic library cufft64_100.dll
2020-10-05 20:44:03.116889: I tensorflow/stream_executor/platform/default/dso_loader.cc:44] Successfully opened dynamic library curand64_100.dll
2020-10-05 20:44:03.117228: I tensorflow/stream_executor/platform/default/dso_loader.cc:44] Successfully opened dynamic library cusolver64_100.dll
2020-10-05 20:44:03.117572: I tensorflow/stream_executor/platform/default/dso_loader.cc:44] Successfully opened dynamic library cusparse64_100.dll
2020-10-05 20:44:03.117915: I tensorflow/stream_executor/platform/default/dso_loader.cc:44] Successfully opened dynamic library cudnn64_7.dll
2020-10-05 20:44:03.118471: I tensorflow/core/common_runtime/gpu/gpu_device.cc:1746] Adding visible gpu devices: 0
2020-10-05 20:44:03.118776: I tensorflow/core/common_runtime/gpu/gpu_device.cc:1159] Device interconnect StreamExecutor with strength 1 edge matrix:
2020-10-05 20:44:03.119125: I tensorflow/core/common_runtime/gpu/gpu_device.cc:1165]      0 
2020-10-05 20:44:03.119344: I tensorflow/core/common_runtime/gpu/gpu_device.cc:1178] 0:   N 
2020-10-05 20:44:03.119813: I tensorflow/core/common_runtime/gpu/gpu_device.cc:1304] Created TensorFlow device (/job:localhost/replica:0/task:0/device:GPU:0 with 8686 MB memory) -> physical GPU (device: 0, name: GeForce RTX 2080 Ti, pci bus id: 0000:73:00.0, compute capability: 7.5)
[       OK ] JITTest.testDefunNoJitScope_function
[ RUN      ] JITTest.testDefunNoJitScope_v1_graph
2020-10-05 20:44:03.133976: I tensorflow/core/common_runtime/gpu/gpu_device.cc:1618] Found device 0 with properties: 
name: GeForce RTX 2080 Ti major: 7 minor: 5 memoryClockRate(GHz): 1.65
pciBusID: 0000:73:00.0
2020-10-05 20:44:03.134497: I tensorflow/stream_executor/platform/default/dso_loader.cc:44] Successfully opened dynamic library cudart64_100.dll
2020-10-05 20:44:03.134838: I tensorflow/stream_executor/platform/default/dso_loader.cc:44] Successfully opened dynamic library cublas64_100.dll
2020-10-05 20:44:03.135187: I tensorflow/stream_executor/platform/default/dso_loader.cc:44] Successfully opened dynamic library cufft64_100.dll
2020-10-05 20:44:03.135527: I tensorflow/stream_executor/platform/default/dso_loader.cc:44] Successfully opened dynamic library curand64_100.dll
2020-10-05 20:44:03.135868: I tensorflow/stream_executor/platform/default/dso_loader.cc:44] Successfully opened dynamic library cusolver64_100.dll
2020-10-05 20:44:03.136213: I tensorflow/stream_executor/platform/default/dso_loader.cc:44] Successfully opened dynamic library cusparse64_100.dll
2020-10-05 20:44:03.136578: I tensorflow/stream_executor/platform/default/dso_loader.cc:44] Successfully opened dynamic library cudnn64_7.dll
2020-10-05 20:44:03.137164: I tensorflow/core/common_runtime/gpu/gpu_device.cc:1746] Adding visible gpu devices: 0
2020-10-05 20:44:03.137484: I tensorflow/core/common_runtime/gpu/gpu_device.cc:1159] Device interconnect StreamExecutor with strength 1 edge matrix:
2020-10-05 20:44:03.137848: I tensorflow/core/common_runtime/gpu/gpu_device.cc:1165]      0 
2020-10-05 20:44:03.138071: I tensorflow/core/common_runtime/gpu/gpu_device.cc:1178] 0:   N 
2020-10-05 20:44:03.138539: I tensorflow/core/common_runtime/gpu/gpu_device.cc:1304] Created TensorFlow device (/job:localhost/replica:0/task:0/device:GPU:0 with 8686 MB memory) -> physical GPU (device: 0, name: GeForce RTX 2080 Ti, pci bus id: 0000:73:00.0, compute capability: 7.5)
[       OK ] JITTest.testDefunNoJitScope_v1_graph
[ RUN      ] JITTest.testJITCreateOpsLambda_function
WARNING:tensorflow:Entity <function build_as_function_and_v1_graph.<locals>.decorator.<locals>.decorated.<locals>.function_in_eager at 0x0000017D891F2F28> could not be transformed and will be executed as-is. Please report this to the AutoGraph team. When filing the bug, set the verbosity to 10 (on Linux, `export AUTOGRAPH_VERBOSITY=10`) and attach the full output. Cause: 'NoneType' object has no attribute '_fields'
W1005 20:44:03.157937 18708 ag_logging.py:146] Entity <function build_as_function_and_v1_graph.<locals>.decorator.<locals>.decorated.<locals>.function_in_eager at 0x0000017D891F2F28> could not be transformed and will be executed as-is. Please report this to the AutoGraph team. When filing the bug, set the verbosity to 10 (on Linux, `export AUTOGRAPH_VERBOSITY=10`) and attach the full output. Cause: 'NoneType' object has no attribute '_fields'
2020-10-05 20:44:03.170712: I tensorflow/core/common_runtime/gpu/gpu_device.cc:1618] Found device 0 with properties: 
name: GeForce RTX 2080 Ti major: 7 minor: 5 memoryClockRate(GHz): 1.65
pciBusID: 0000:73:00.0
2020-10-05 20:44:03.171227: I tensorflow/stream_executor/platform/default/dso_loader.cc:44] Successfully opened dynamic library cudart64_100.dll
2020-10-05 20:44:03.171575: I tensorflow/stream_executor/platform/default/dso_loader.cc:44] Successfully opened dynamic library cublas64_100.dll
2020-10-05 20:44:03.171919: I tensorflow/stream_executor/platform/default/dso_loader.cc:44] Successfully opened dynamic library cufft64_100.dll
2020-10-05 20:44:03.172262: I tensorflow/stream_executor/platform/default/dso_loader.cc:44] Successfully opened dynamic library curand64_100.dll
2020-10-05 20:44:03.172607: I tensorflow/stream_executor/platform/default/dso_loader.cc:44] Successfully opened dynamic library cusolver64_100.dll
2020-10-05 20:44:03.172955: I tensorflow/stream_executor/platform/default/dso_loader.cc:44] Successfully opened dynamic library cusparse64_100.dll
2020-10-05 20:44:03.173297: I tensorflow/stream_executor/platform/default/dso_loader.cc:44] Successfully opened dynamic library cudnn64_7.dll
2020-10-05 20:44:03.173893: I tensorflow/core/common_runtime/gpu/gpu_device.cc:1746] Adding visible gpu devices: 0
2020-10-05 20:44:03.174195: I tensorflow/core/common_runtime/gpu/gpu_device.cc:1159] Device interconnect StreamExecutor with strength 1 edge matrix:
2020-10-05 20:44:03.174541: I tensorflow/core/common_runtime/gpu/gpu_device.cc:1165]      0 
2020-10-05 20:44:03.174757: I tensorflow/core/common_runtime/gpu/gpu_device.cc:1178] 0:   N 
2020-10-05 20:44:03.175227: I tensorflow/core/common_runtime/gpu/gpu_device.cc:1304] Created TensorFlow device (/job:localhost/replica:0/task:0/device:GPU:0 with 8686 MB memory) -> physical GPU (device: 0, name: GeForce RTX 2080 Ti, pci bus id: 0000:73:00.0, compute capability: 7.5)
[  FAILED  ] JITTest.testJITCreateOpsLambda_function
[ RUN      ] JITTest.testJITCreateOpsLambda_v1_graph
2020-10-05 20:44:03.178704: I tensorflow/core/common_runtime/gpu/gpu_device.cc:1618] Found device 0 with properties: 
name: GeForce RTX 2080 Ti major: 7 minor: 5 memoryClockRate(GHz): 1.65
pciBusID: 0000:73:00.0
2020-10-05 20:44:03.179215: I tensorflow/stream_executor/platform/default/dso_loader.cc:44] Successfully opened dynamic library cudart64_100.dll
2020-10-05 20:44:03.179555: I tensorflow/stream_executor/platform/default/dso_loader.cc:44] Successfully opened dynamic library cublas64_100.dll
2020-10-05 20:44:03.179892: I tensorflow/stream_executor/platform/default/dso_loader.cc:44] Successfully opened dynamic library cufft64_100.dll
2020-10-05 20:44:03.180228: I tensorflow/stream_executor/platform/default/dso_loader.cc:44] Successfully opened dynamic library curand64_100.dll
2020-10-05 20:44:03.180564: I tensorflow/stream_executor/platform/default/dso_loader.cc:44] Successfully opened dynamic library cusolver64_100.dll
2020-10-05 20:44:03.180905: I tensorflow/stream_executor/platform/default/dso_loader.cc:44] Successfully opened dynamic library cusparse64_100.dll
2020-10-05 20:44:03.181251: I tensorflow/stream_executor/platform/default/dso_loader.cc:44] Successfully opened dynamic library cudnn64_7.dll
2020-10-05 20:44:03.181800: I tensorflow/core/common_runtime/gpu/gpu_device.cc:1746] Adding visible gpu devices: 0
2020-10-05 20:44:03.182099: I tensorflow/core/common_runtime/gpu/gpu_device.cc:1159] Device interconnect StreamExecutor with strength 1 edge matrix:
2020-10-05 20:44:03.182448: I tensorflow/core/common_runtime/gpu/gpu_device.cc:1165]      0 
2020-10-05 20:44:03.182664: I tensorflow/core/common_runtime/gpu/gpu_device.cc:1178] 0:   N 
2020-10-05 20:44:03.183130: I tensorflow/core/common_runtime/gpu/gpu_device.cc:1304] Created TensorFlow device (/job:localhost/replica:0/task:0/device:GPU:0 with 8686 MB memory) -> physical GPU (device: 0, name: GeForce RTX 2080 Ti, pci bus id: 0000:73:00.0, compute capability: 7.5)
[  FAILED  ] JITTest.testJITCreateOpsLambda_v1_graph
[ RUN      ] JITTest.testJITInEager
[  SKIPPED ] JITTest.testJITInEager
[ RUN      ] JITTest.testJITVariableSeed_function
WARNING:tensorflow:Entity <function build_as_function_and_v1_graph.<locals>.decorator.<locals>.decorated.<locals>.function_in_eager at 0x0000017D89291378> could not be transformed and will be executed as-is. Please report this to the AutoGraph team. When filing the bug, set the verbosity to 10 (on Linux, `export AUTOGRAPH_VERBOSITY=10`) and attach the full output. Cause: 'NoneType' object has no attribute '_fields'
W1005 20:44:03.204804 18708 ag_logging.py:146] Entity <function build_as_function_and_v1_graph.<locals>.decorator.<locals>.decorated.<locals>.function_in_eager at 0x0000017D89291378> could not be transformed and will be executed as-is. Please report this to the AutoGraph team. When filing the bug, set the verbosity to 10 (on Linux, `export AUTOGRAPH_VERBOSITY=10`) and attach the full output. Cause: 'NoneType' object has no attribute '_fields'
2020-10-05 20:44:03.213258: I tensorflow/core/common_runtime/gpu/gpu_device.cc:1618] Found device 0 with properties: 
name: GeForce RTX 2080 Ti major: 7 minor: 5 memoryClockRate(GHz): 1.65
pciBusID: 0000:73:00.0
2020-10-05 20:44:03.213777: I tensorflow/stream_executor/platform/default/dso_loader.cc:44] Successfully opened dynamic library cudart64_100.dll
2020-10-05 20:44:03.214125: I tensorflow/stream_executor/platform/default/dso_loader.cc:44] Successfully opened dynamic library cublas64_100.dll
2020-10-05 20:44:03.214467: I tensorflow/stream_executor/platform/default/dso_loader.cc:44] Successfully opened dynamic library cufft64_100.dll
2020-10-05 20:44:03.214803: I tensorflow/stream_executor/platform/default/dso_loader.cc:44] Successfully opened dynamic library curand64_100.dll
2020-10-05 20:44:03.215140: I tensorflow/stream_executor/platform/default/dso_loader.cc:44] Successfully opened dynamic library cusolver64_100.dll
2020-10-05 20:44:03.215482: I tensorflow/stream_executor/platform/default/dso_loader.cc:44] Successfully opened dynamic library cusparse64_100.dll
2020-10-05 20:44:03.215823: I tensorflow/stream_executor/platform/default/dso_loader.cc:44] Successfully opened dynamic library cudnn64_7.dll
2020-10-05 20:44:03.216369: I tensorflow/core/common_runtime/gpu/gpu_device.cc:1746] Adding visible gpu devices: 0
2020-10-05 20:44:03.216672: I tensorflow/core/common_runtime/gpu/gpu_device.cc:1159] Device interconnect StreamExecutor with strength 1 edge matrix:
2020-10-05 20:44:03.217024: I tensorflow/core/common_runtime/gpu/gpu_device.cc:1165]      0 
2020-10-05 20:44:03.217242: I tensorflow/core/common_runtime/gpu/gpu_device.cc:1178] 0:   N 
2020-10-05 20:44:03.217705: I tensorflow/core/common_runtime/gpu/gpu_device.cc:1304] Created TensorFlow device (/job:localhost/replica:0/task:0/device:GPU:0 with 8686 MB memory) -> physical GPU (device: 0, name: GeForce RTX 2080 Ti, pci bus id: 0000:73:00.0, compute capability: 7.5)
[  FAILED  ] JITTest.testJITVariableSeed_function
[ RUN      ] JITTest.testJITVariableSeed_v1_graph
2020-10-05 20:44:03.221465: I tensorflow/core/common_runtime/gpu/gpu_device.cc:1618] Found device 0 with properties: 
name: GeForce RTX 2080 Ti major: 7 minor: 5 memoryClockRate(GHz): 1.65
pciBusID: 0000:73:00.0
2020-10-05 20:44:03.221977: I tensorflow/stream_executor/platform/default/dso_loader.cc:44] Successfully opened dynamic library cudart64_100.dll
2020-10-05 20:44:03.222316: I tensorflow/stream_executor/platform/default/dso_loader.cc:44] Successfully opened dynamic library cublas64_100.dll
2020-10-05 20:44:03.222690: I tensorflow/stream_executor/platform/default/dso_loader.cc:44] Successfully opened dynamic library cufft64_100.dll
2020-10-05 20:44:03.223050: I tensorflow/stream_executor/platform/default/dso_loader.cc:44] Successfully opened dynamic library curand64_100.dll
2020-10-05 20:44:03.223415: I tensorflow/stream_executor/platform/default/dso_loader.cc:44] Successfully opened dynamic library cusolver64_100.dll
2020-10-05 20:44:03.223757: I tensorflow/stream_executor/platform/default/dso_loader.cc:44] Successfully opened dynamic library cusparse64_100.dll
2020-10-05 20:44:03.224099: I tensorflow/stream_executor/platform/default/dso_loader.cc:44] Successfully opened dynamic library cudnn64_7.dll
2020-10-05 20:44:03.224644: I tensorflow/core/common_runtime/gpu/gpu_device.cc:1746] Adding visible gpu devices: 0
2020-10-05 20:44:03.224941: I tensorflow/core/common_runtime/gpu/gpu_device.cc:1159] Device interconnect StreamExecutor with strength 1 edge matrix:
2020-10-05 20:44:03.225294: I tensorflow/core/common_runtime/gpu/gpu_device.cc:1165]      0 
2020-10-05 20:44:03.225511: I tensorflow/core/common_runtime/gpu/gpu_device.cc:1178] 0:   N 
2020-10-05 20:44:03.225978: I tensorflow/core/common_runtime/gpu/gpu_device.cc:1304] Created TensorFlow device (/job:localhost/replica:0/task:0/device:GPU:0 with 8686 MB memory) -> physical GPU (device: 0, name: GeForce RTX 2080 Ti, pci bus id: 0000:73:00.0, compute capability: 7.5)
[  FAILED  ] JITTest.testJITVariableSeed_v1_graph
[ RUN      ] JITTest.testJITXlaScope_function
WARNING:tensorflow:Entity <function build_as_function_and_v1_graph.<locals>.decorator.<locals>.decorated.<locals>.function_in_eager at 0x0000017D89291378> could not be transformed and will be executed as-is. Please report this to the AutoGraph team. When filing the bug, set the verbosity to 10 (on Linux, `export AUTOGRAPH_VERBOSITY=10`) and attach the full output. Cause: 'NoneType' object has no attribute '_fields'
W1005 20:44:03.251668 18708 ag_logging.py:146] Entity <function build_as_function_and_v1_graph.<locals>.decorator.<locals>.decorated.<locals>.function_in_eager at 0x0000017D89291378> could not be transformed and will be executed as-is. Please report this to the AutoGraph team. When filing the bug, set the verbosity to 10 (on Linux, `export AUTOGRAPH_VERBOSITY=10`) and attach the full output. Cause: 'NoneType' object has no attribute '_fields'
2020-10-05 20:44:03.255876: I tensorflow/core/common_runtime/gpu/gpu_device.cc:1618] Found device 0 with properties: 
name: GeForce RTX 2080 Ti major: 7 minor: 5 memoryClockRate(GHz): 1.65
pciBusID: 0000:73:00.0
2020-10-05 20:44:03.256389: I tensorflow/stream_executor/platform/default/dso_loader.cc:44] Successfully opened dynamic library cudart64_100.dll
2020-10-05 20:44:03.256733: I tensorflow/stream_executor/platform/default/dso_loader.cc:44] Successfully opened dynamic library cublas64_100.dll
2020-10-05 20:44:03.257077: I tensorflow/stream_executor/platform/default/dso_loader.cc:44] Successfully opened dynamic library cufft64_100.dll
2020-10-05 20:44:03.257418: I tensorflow/stream_executor/platform/default/dso_loader.cc:44] Successfully opened dynamic library curand64_100.dll
2020-10-05 20:44:03.257758: I tensorflow/stream_executor/platform/default/dso_loader.cc:44] Successfully opened dynamic library cusolver64_100.dll
2020-10-05 20:44:03.258113: I tensorflow/stream_executor/platform/default/dso_loader.cc:44] Successfully opened dynamic library cusparse64_100.dll
2020-10-05 20:44:03.258458: I tensorflow/stream_executor/platform/default/dso_loader.cc:44] Successfully opened dynamic library cudnn64_7.dll
2020-10-05 20:44:03.259013: I tensorflow/core/common_runtime/gpu/gpu_device.cc:1746] Adding visible gpu devices: 0
2020-10-05 20:44:03.259311: I tensorflow/core/common_runtime/gpu/gpu_device.cc:1159] Device interconnect StreamExecutor with strength 1 edge matrix:
2020-10-05 20:44:03.259657: I tensorflow/core/common_runtime/gpu/gpu_device.cc:1165]      0 
2020-10-05 20:44:03.259874: I tensorflow/core/common_runtime/gpu/gpu_device.cc:1178] 0:   N 
2020-10-05 20:44:03.260338: I tensorflow/core/common_runtime/gpu/gpu_device.cc:1304] Created TensorFlow device (/job:localhost/replica:0/task:0/device:GPU:0 with 8686 MB memory) -> physical GPU (device: 0, name: GeForce RTX 2080 Ti, pci bus id: 0000:73:00.0, compute capability: 7.5)
[  FAILED  ] JITTest.testJITXlaScope_function
[ RUN      ] JITTest.testJITXlaScope_v1_graph
2020-10-05 20:44:03.267399: I tensorflow/core/common_runtime/gpu/gpu_device.cc:1618] Found device 0 with properties: 
name: GeForce RTX 2080 Ti major: 7 minor: 5 memoryClockRate(GHz): 1.65
pciBusID: 0000:73:00.0
2020-10-05 20:44:03.269311: I tensorflow/stream_executor/platform/default/dso_loader.cc:44] Successfully opened dynamic library cudart64_100.dll
2020-10-05 20:44:03.270598: I tensorflow/stream_executor/platform/default/dso_loader.cc:44] Successfully opened dynamic library cublas64_100.dll
2020-10-05 20:44:03.271895: I tensorflow/stream_executor/platform/default/dso_loader.cc:44] Successfully opened dynamic library cufft64_100.dll
2020-10-05 20:44:03.273172: I tensorflow/stream_executor/platform/default/dso_loader.cc:44] Successfully opened dynamic library curand64_100.dll
2020-10-05 20:44:03.274458: I tensorflow/stream_executor/platform/default/dso_loader.cc:44] Successfully opened dynamic library cusolver64_100.dll
2020-10-05 20:44:03.275762: I tensorflow/stream_executor/platform/default/dso_loader.cc:44] Successfully opened dynamic library cusparse64_100.dll
2020-10-05 20:44:03.277064: I tensorflow/stream_executor/platform/default/dso_loader.cc:44] Successfully opened dynamic library cudnn64_7.dll
2020-10-05 20:44:03.279011: I tensorflow/core/common_runtime/gpu/gpu_device.cc:1746] Adding visible gpu devices: 0
2020-10-05 20:44:03.280122: I tensorflow/core/common_runtime/gpu/gpu_device.cc:1159] Device interconnect StreamExecutor with strength 1 edge matrix:
2020-10-05 20:44:03.281434: I tensorflow/core/common_runtime/gpu/gpu_device.cc:1165]      0 
2020-10-05 20:44:03.282255: I tensorflow/core/common_runtime/gpu/gpu_device.cc:1178] 0:   N 
2020-10-05 20:44:03.283878: I tensorflow/core/common_runtime/gpu/gpu_device.cc:1304] Created TensorFlow device (/job:localhost/replica:0/task:0/device:GPU:0 with 8686 MB memory) -> physical GPU (device: 0, name: GeForce RTX 2080 Ti, pci bus id: 0000:73:00.0, compute capability: 7.5)
[  FAILED  ] JITTest.testJITXlaScope_v1_graph
[ RUN      ] JITTest.test_session
[  SKIPPED ] JITTest.test_session
======================================================================
ERROR: testCompilationGradientScopeNames_function (__main__.CompilationEnabledInGradientTest)
CompilationEnabledInGradientTest.testCompilationGradientScopeNames_function
testCompilationGradientScopeNames_function('function')
----------------------------------------------------------------------
Traceback (most recent call last):
  File "C:\ProgramData\Anaconda3\envs\keras\lib\site-packages\absl\testing\parameterized.py", line 284, in bound_param_test
    return test_method(self, *testcase_params)
  File "C:\ProgramData\Anaconda3\envs\keras\lib\site-packages\tensorflow_core\python\framework\test_util.py", line 993, in decorated
    function_in_eager()
  File "C:\ProgramData\Anaconda3\envs\keras\lib\site-packages\tensorflow_core\python\eager\def_function.py", line 449, in __call__
    self._initialize(args, kwds, add_initializers_to=initializer_map)
  File "C:\ProgramData\Anaconda3\envs\keras\lib\site-packages\tensorflow_core\python\eager\def_function.py", line 392, in _initialize
    *args, **kwds))
  File "C:\ProgramData\Anaconda3\envs\keras\lib\site-packages\tensorflow_core\python\eager\function.py", line 1847, in _get_concrete_function_internal_garbage_collected
    graph_function, _, _ = self._maybe_define_function(args, kwargs)
  File "C:\ProgramData\Anaconda3\envs\keras\lib\site-packages\tensorflow_core\python\eager\function.py", line 2147, in _maybe_define_function
    graph_function = self._create_graph_function(args, kwargs)
  File "C:\ProgramData\Anaconda3\envs\keras\lib\site-packages\tensorflow_core\python\eager\function.py", line 2038, in _create_graph_function
    capture_by_value=self._capture_by_value),
  File "C:\ProgramData\Anaconda3\envs\keras\lib\site-packages\tensorflow_core\python\framework\func_graph.py", line 915, in func_graph_from_py_func
    func_outputs = python_func(*func_args, **func_kwargs)
  File "C:\ProgramData\Anaconda3\envs\keras\lib\site-packages\tensorflow_core\python\eager\def_function.py", line 335, in wrapped_fn
    return weak_wrapped_fn().__wrapped__(*args, **kwds)
  File "C:\ProgramData\Anaconda3\envs\keras\lib\site-packages\tensorflow_core\python\framework\func_graph.py", line 905, in wrapper
    raise e.ag_error_metadata.to_exception(e)
tensorflow.python.autograph.impl.api.StagingError: in converted code:

    C:\ProgramData\Anaconda3\envs\keras\lib\site-packages\tensorflow_core\python\framework\test_util.py:987 function_in_eager
        f(self, *args, **kwargs)
    jit_test.py:439 testCompilationGradientScopeNames
        with jit.experimental_jit_scope():
    C:\ProgramData\Anaconda3\envs\keras\lib\contextlib.py:81 __enter__
        return next(self.gen)
    C:\ProgramData\Anaconda3\envs\keras\lib\site-packages\tensorflow_core\python\compiler\xla\jit.py:108 experimental_jit_scope
        xla_scope_counter = xla_scope_counter[0]

    IndexError: list index out of range


======================================================================
ERROR: testCompilationGradientScopeNames_v1_graph (__main__.CompilationEnabledInGradientTest)
CompilationEnabledInGradientTest.testCompilationGradientScopeNames_v1_graph
testCompilationGradientScopeNames_v1_graph('v1_graph')
----------------------------------------------------------------------
Traceback (most recent call last):
  File "C:\ProgramData\Anaconda3\envs\keras\lib\site-packages\absl\testing\parameterized.py", line 284, in bound_param_test
    return test_method(self, *testcase_params)
  File "C:\ProgramData\Anaconda3\envs\keras\lib\site-packages\tensorflow_core\python\framework\test_util.py", line 982, in decorated
    f(self, *args, **kwargs)
  File "jit_test.py", line 439, in testCompilationGradientScopeNames
    with jit.experimental_jit_scope():
  File "C:\ProgramData\Anaconda3\envs\keras\lib\contextlib.py", line 81, in __enter__
    return next(self.gen)
  File "C:\ProgramData\Anaconda3\envs\keras\lib\site-packages\tensorflow_core\python\compiler\xla\jit.py", line 108, in experimental_jit_scope
    xla_scope_counter = xla_scope_counter[0]
IndexError: list index out of range

======================================================================
ERROR: testCompilationInGradient_function (__main__.CompilationEnabledInGradientTest)
CompilationEnabledInGradientTest.testCompilationInGradient_function
testCompilationInGradient_function('function')
----------------------------------------------------------------------
Traceback (most recent call last):
  File "C:\ProgramData\Anaconda3\envs\keras\lib\site-packages\absl\testing\parameterized.py", line 284, in bound_param_test
    return test_method(self, *testcase_params)
  File "C:\ProgramData\Anaconda3\envs\keras\lib\site-packages\tensorflow_core\python\framework\test_util.py", line 993, in decorated
    function_in_eager()
  File "C:\ProgramData\Anaconda3\envs\keras\lib\site-packages\tensorflow_core\python\eager\def_function.py", line 449, in __call__
    self._initialize(args, kwds, add_initializers_to=initializer_map)
  File "C:\ProgramData\Anaconda3\envs\keras\lib\site-packages\tensorflow_core\python\eager\def_function.py", line 392, in _initialize
    *args, **kwds))
  File "C:\ProgramData\Anaconda3\envs\keras\lib\site-packages\tensorflow_core\python\eager\function.py", line 1847, in _get_concrete_function_internal_garbage_collected
    graph_function, _, _ = self._maybe_define_function(args, kwargs)
  File "C:\ProgramData\Anaconda3\envs\keras\lib\site-packages\tensorflow_core\python\eager\function.py", line 2147, in _maybe_define_function
    graph_function = self._create_graph_function(args, kwargs)
  File "C:\ProgramData\Anaconda3\envs\keras\lib\site-packages\tensorflow_core\python\eager\function.py", line 2038, in _create_graph_function
    capture_by_value=self._capture_by_value),
  File "C:\ProgramData\Anaconda3\envs\keras\lib\site-packages\tensorflow_core\python\framework\func_graph.py", line 915, in func_graph_from_py_func
    func_outputs = python_func(*func_args, **func_kwargs)
  File "C:\ProgramData\Anaconda3\envs\keras\lib\site-packages\tensorflow_core\python\eager\def_function.py", line 335, in wrapped_fn
    return weak_wrapped_fn().__wrapped__(*args, **kwds)
  File "C:\ProgramData\Anaconda3\envs\keras\lib\site-packages\tensorflow_core\python\framework\func_graph.py", line 905, in wrapper
    raise e.ag_error_metadata.to_exception(e)
tensorflow.python.autograph.impl.api.StagingError: in converted code:

    C:\ProgramData\Anaconda3\envs\keras\lib\site-packages\tensorflow_core\python\framework\test_util.py:987 function_in_eager
        f(self, *args, **kwargs)
    jit_test.py:395 testCompilationInGradient
        with jit.experimental_jit_scope():
    C:\ProgramData\Anaconda3\envs\keras\lib\contextlib.py:81 __enter__
        return next(self.gen)
    C:\ProgramData\Anaconda3\envs\keras\lib\site-packages\tensorflow_core\python\compiler\xla\jit.py:108 experimental_jit_scope
        xla_scope_counter = xla_scope_counter[0]

    IndexError: list index out of range


======================================================================
ERROR: testCompilationInGradient_v1_graph (__main__.CompilationEnabledInGradientTest)
CompilationEnabledInGradientTest.testCompilationInGradient_v1_graph
testCompilationInGradient_v1_graph('v1_graph')
----------------------------------------------------------------------
Traceback (most recent call last):
  File "C:\ProgramData\Anaconda3\envs\keras\lib\site-packages\absl\testing\parameterized.py", line 284, in bound_param_test
    return test_method(self, *testcase_params)
  File "C:\ProgramData\Anaconda3\envs\keras\lib\site-packages\tensorflow_core\python\framework\test_util.py", line 982, in decorated
    f(self, *args, **kwargs)
  File "jit_test.py", line 395, in testCompilationInGradient
    with jit.experimental_jit_scope():
  File "C:\ProgramData\Anaconda3\envs\keras\lib\contextlib.py", line 81, in __enter__
    return next(self.gen)
  File "C:\ProgramData\Anaconda3\envs\keras\lib\site-packages\tensorflow_core\python\compiler\xla\jit.py", line 108, in experimental_jit_scope
    xla_scope_counter = xla_scope_counter[0]
IndexError: list index out of range

======================================================================
ERROR: testCompilationSeparateGradientScopeNames_function (__main__.CompilationEnabledInGradientTest)
CompilationEnabledInGradientTest.testCompilationSeparateGradientScopeNames_function
testCompilationSeparateGradientScopeNames_function('function')
----------------------------------------------------------------------
Traceback (most recent call last):
  File "C:\ProgramData\Anaconda3\envs\keras\lib\site-packages\absl\testing\parameterized.py", line 284, in bound_param_test
    return test_method(self, *testcase_params)
  File "C:\ProgramData\Anaconda3\envs\keras\lib\site-packages\tensorflow_core\python\framework\test_util.py", line 993, in decorated
    function_in_eager()
  File "C:\ProgramData\Anaconda3\envs\keras\lib\site-packages\tensorflow_core\python\eager\def_function.py", line 449, in __call__
    self._initialize(args, kwds, add_initializers_to=initializer_map)
  File "C:\ProgramData\Anaconda3\envs\keras\lib\site-packages\tensorflow_core\python\eager\def_function.py", line 392, in _initialize
    *args, **kwds))
  File "C:\ProgramData\Anaconda3\envs\keras\lib\site-packages\tensorflow_core\python\eager\function.py", line 1847, in _get_concrete_function_internal_garbage_collected
    graph_function, _, _ = self._maybe_define_function(args, kwargs)
  File "C:\ProgramData\Anaconda3\envs\keras\lib\site-packages\tensorflow_core\python\eager\function.py", line 2147, in _maybe_define_function
    graph_function = self._create_graph_function(args, kwargs)
  File "C:\ProgramData\Anaconda3\envs\keras\lib\site-packages\tensorflow_core\python\eager\function.py", line 2038, in _create_graph_function
    capture_by_value=self._capture_by_value),
  File "C:\ProgramData\Anaconda3\envs\keras\lib\site-packages\tensorflow_core\python\framework\func_graph.py", line 915, in func_graph_from_py_func
    func_outputs = python_func(*func_args, **func_kwargs)
  File "C:\ProgramData\Anaconda3\envs\keras\lib\site-packages\tensorflow_core\python\eager\def_function.py", line 335, in wrapped_fn
    return weak_wrapped_fn().__wrapped__(*args, **kwds)
  File "C:\ProgramData\Anaconda3\envs\keras\lib\site-packages\tensorflow_core\python\framework\func_graph.py", line 905, in wrapper
    raise e.ag_error_metadata.to_exception(e)
tensorflow.python.autograph.impl.api.StagingError: in converted code:

    C:\ProgramData\Anaconda3\envs\keras\lib\site-packages\tensorflow_core\python\framework\test_util.py:987 function_in_eager
        f(self, *args, **kwargs)
    jit_test.py:485 testCompilationSeparateGradientScopeNames
        with jit.experimental_jit_scope(True, separate_compiled_gradients=True):
    C:\ProgramData\Anaconda3\envs\keras\lib\contextlib.py:81 __enter__
        return next(self.gen)
    C:\ProgramData\Anaconda3\envs\keras\lib\site-packages\tensorflow_core\python\compiler\xla\jit.py:108 experimental_jit_scope
        xla_scope_counter = xla_scope_counter[0]

    IndexError: list index out of range


======================================================================
ERROR: testCompilationSeparateGradientScopeNames_v1_graph (__main__.CompilationEnabledInGradientTest)
CompilationEnabledInGradientTest.testCompilationSeparateGradientScopeNames_v1_graph
testCompilationSeparateGradientScopeNames_v1_graph('v1_graph')
----------------------------------------------------------------------
Traceback (most recent call last):
  File "C:\ProgramData\Anaconda3\envs\keras\lib\site-packages\absl\testing\parameterized.py", line 284, in bound_param_test
    return test_method(self, *testcase_params)
  File "C:\ProgramData\Anaconda3\envs\keras\lib\site-packages\tensorflow_core\python\framework\test_util.py", line 982, in decorated
    f(self, *args, **kwargs)
  File "jit_test.py", line 485, in testCompilationSeparateGradientScopeNames
    with jit.experimental_jit_scope(True, separate_compiled_gradients=True):
  File "C:\ProgramData\Anaconda3\envs\keras\lib\contextlib.py", line 81, in __enter__
    return next(self.gen)
  File "C:\ProgramData\Anaconda3\envs\keras\lib\site-packages\tensorflow_core\python\compiler\xla\jit.py", line 108, in experimental_jit_scope
    xla_scope_counter = xla_scope_counter[0]
IndexError: list index out of range

======================================================================
ERROR: testPlaysNicelyWithDefunSeparateGradientScope_function (__main__.CompilationEnabledInGradientTest)
CompilationEnabledInGradientTest.testPlaysNicelyWithDefunSeparateGradientScope_function
testPlaysNicelyWithDefunSeparateGradientScope_function('function')
----------------------------------------------------------------------
Traceback (most recent call last):
  File "C:\ProgramData\Anaconda3\envs\keras\lib\site-packages\absl\testing\parameterized.py", line 284, in bound_param_test
    return test_method(self, *testcase_params)
  File "C:\ProgramData\Anaconda3\envs\keras\lib\site-packages\tensorflow_core\python\framework\test_util.py", line 993, in decorated
    function_in_eager()
  File "C:\ProgramData\Anaconda3\envs\keras\lib\site-packages\tensorflow_core\python\eager\def_function.py", line 449, in __call__
    self._initialize(args, kwds, add_initializers_to=initializer_map)
  File "C:\ProgramData\Anaconda3\envs\keras\lib\site-packages\tensorflow_core\python\eager\def_function.py", line 392, in _initialize
    *args, **kwds))
  File "C:\ProgramData\Anaconda3\envs\keras\lib\site-packages\tensorflow_core\python\eager\function.py", line 1847, in _get_concrete_function_internal_garbage_collected
    graph_function, _, _ = self._maybe_define_function(args, kwargs)
  File "C:\ProgramData\Anaconda3\envs\keras\lib\site-packages\tensorflow_core\python\eager\function.py", line 2147, in _maybe_define_function
    graph_function = self._create_graph_function(args, kwargs)
  File "C:\ProgramData\Anaconda3\envs\keras\lib\site-packages\tensorflow_core\python\eager\function.py", line 2038, in _create_graph_function
    capture_by_value=self._capture_by_value),
  File "C:\ProgramData\Anaconda3\envs\keras\lib\site-packages\tensorflow_core\python\framework\func_graph.py", line 915, in func_graph_from_py_func
    func_outputs = python_func(*func_args, **func_kwargs)
  File "C:\ProgramData\Anaconda3\envs\keras\lib\site-packages\tensorflow_core\python\eager\def_function.py", line 335, in wrapped_fn
    return weak_wrapped_fn().__wrapped__(*args, **kwds)
  File "C:\ProgramData\Anaconda3\envs\keras\lib\site-packages\tensorflow_core\python\framework\func_graph.py", line 905, in wrapper
    raise e.ag_error_metadata.to_exception(e)
tensorflow.python.autograph.impl.api.StagingError: in converted code:

    C:\ProgramData\Anaconda3\envs\keras\lib\site-packages\tensorflow_core\python\framework\test_util.py:987 function_in_eager
        f(self, *args, **kwargs)
    jit_test.py:587 testPlaysNicelyWithDefunSeparateGradientScope
        with jit.experimental_jit_scope(True):
    C:\ProgramData\Anaconda3\envs\keras\lib\contextlib.py:81 __enter__
        return next(self.gen)
    C:\ProgramData\Anaconda3\envs\keras\lib\site-packages\tensorflow_core\python\compiler\xla\jit.py:108 experimental_jit_scope
        xla_scope_counter = xla_scope_counter[0]

    IndexError: list index out of range


======================================================================
ERROR: testPlaysNicelyWithDefunSeparateGradientScope_v1_graph (__main__.CompilationEnabledInGradientTest)
CompilationEnabledInGradientTest.testPlaysNicelyWithDefunSeparateGradientScope_v1_graph
testPlaysNicelyWithDefunSeparateGradientScope_v1_graph('v1_graph')
----------------------------------------------------------------------
Traceback (most recent call last):
  File "C:\ProgramData\Anaconda3\envs\keras\lib\site-packages\absl\testing\parameterized.py", line 284, in bound_param_test
    return test_method(self, *testcase_params)
  File "C:\ProgramData\Anaconda3\envs\keras\lib\site-packages\tensorflow_core\python\framework\test_util.py", line 982, in decorated
    f(self, *args, **kwargs)
  File "jit_test.py", line 587, in testPlaysNicelyWithDefunSeparateGradientScope
    with jit.experimental_jit_scope(True):
  File "C:\ProgramData\Anaconda3\envs\keras\lib\contextlib.py", line 81, in __enter__
    return next(self.gen)
  File "C:\ProgramData\Anaconda3\envs\keras\lib\site-packages\tensorflow_core\python\compiler\xla\jit.py", line 108, in experimental_jit_scope
    xla_scope_counter = xla_scope_counter[0]
IndexError: list index out of range

======================================================================
ERROR: testPlaysNicelyWithDefun_function (__main__.CompilationEnabledInGradientTest)
CompilationEnabledInGradientTest.testPlaysNicelyWithDefun_function
testPlaysNicelyWithDefun_function('function')
----------------------------------------------------------------------
Traceback (most recent call last):
  File "C:\ProgramData\Anaconda3\envs\keras\lib\site-packages\absl\testing\parameterized.py", line 284, in bound_param_test
    return test_method(self, *testcase_params)
  File "C:\ProgramData\Anaconda3\envs\keras\lib\site-packages\tensorflow_core\python\framework\test_util.py", line 993, in decorated
    function_in_eager()
  File "C:\ProgramData\Anaconda3\envs\keras\lib\site-packages\tensorflow_core\python\eager\def_function.py", line 449, in __call__
    self._initialize(args, kwds, add_initializers_to=initializer_map)
  File "C:\ProgramData\Anaconda3\envs\keras\lib\site-packages\tensorflow_core\python\eager\def_function.py", line 392, in _initialize
    *args, **kwds))
  File "C:\ProgramData\Anaconda3\envs\keras\lib\site-packages\tensorflow_core\python\eager\function.py", line 1847, in _get_concrete_function_internal_garbage_collected
    graph_function, _, _ = self._maybe_define_function(args, kwargs)
  File "C:\ProgramData\Anaconda3\envs\keras\lib\site-packages\tensorflow_core\python\eager\function.py", line 2147, in _maybe_define_function
    graph_function = self._create_graph_function(args, kwargs)
  File "C:\ProgramData\Anaconda3\envs\keras\lib\site-packages\tensorflow_core\python\eager\function.py", line 2038, in _create_graph_function
    capture_by_value=self._capture_by_value),
  File "C:\ProgramData\Anaconda3\envs\keras\lib\site-packages\tensorflow_core\python\framework\func_graph.py", line 915, in func_graph_from_py_func
    func_outputs = python_func(*func_args, **func_kwargs)
  File "C:\ProgramData\Anaconda3\envs\keras\lib\site-packages\tensorflow_core\python\eager\def_function.py", line 335, in wrapped_fn
    return weak_wrapped_fn().__wrapped__(*args, **kwds)
  File "C:\ProgramData\Anaconda3\envs\keras\lib\site-packages\tensorflow_core\python\framework\func_graph.py", line 905, in wrapper
    raise e.ag_error_metadata.to_exception(e)
tensorflow.python.autograph.impl.api.StagingError: in converted code:

    C:\ProgramData\Anaconda3\envs\keras\lib\site-packages\tensorflow_core\python\framework\test_util.py:987 function_in_eager
        f(self, *args, **kwargs)
    jit_test.py:535 testPlaysNicelyWithDefun
        with jit.experimental_jit_scope(True):
    C:\ProgramData\Anaconda3\envs\keras\lib\contextlib.py:81 __enter__
        return next(self.gen)
    C:\ProgramData\Anaconda3\envs\keras\lib\site-packages\tensorflow_core\python\compiler\xla\jit.py:108 experimental_jit_scope
        xla_scope_counter = xla_scope_counter[0]

    IndexError: list index out of range


======================================================================
ERROR: testPlaysNicelyWithDefun_v1_graph (__main__.CompilationEnabledInGradientTest)
CompilationEnabledInGradientTest.testPlaysNicelyWithDefun_v1_graph
testPlaysNicelyWithDefun_v1_graph('v1_graph')
----------------------------------------------------------------------
Traceback (most recent call last):
  File "C:\ProgramData\Anaconda3\envs\keras\lib\site-packages\absl\testing\parameterized.py", line 284, in bound_param_test
    return test_method(self, *testcase_params)
  File "C:\ProgramData\Anaconda3\envs\keras\lib\site-packages\tensorflow_core\python\framework\test_util.py", line 982, in decorated
    f(self, *args, **kwargs)
  File "jit_test.py", line 535, in testPlaysNicelyWithDefun
    with jit.experimental_jit_scope(True):
  File "C:\ProgramData\Anaconda3\envs\keras\lib\contextlib.py", line 81, in __enter__
    return next(self.gen)
  File "C:\ProgramData\Anaconda3\envs\keras\lib\site-packages\tensorflow_core\python\compiler\xla\jit.py", line 108, in experimental_jit_scope
    xla_scope_counter = xla_scope_counter[0]
IndexError: list index out of range

======================================================================
ERROR: testDefunInheritsJitScope_function (__main__.JITTest)
JITTest.testDefunInheritsJitScope_function
testDefunInheritsJitScope_function('function')
----------------------------------------------------------------------
Traceback (most recent call last):
  File "C:\ProgramData\Anaconda3\envs\keras\lib\site-packages\absl\testing\parameterized.py", line 284, in bound_param_test
    return test_method(self, *testcase_params)
  File "C:\ProgramData\Anaconda3\envs\keras\lib\site-packages\tensorflow_core\python\framework\test_util.py", line 993, in decorated
    function_in_eager()
  File "C:\ProgramData\Anaconda3\envs\keras\lib\site-packages\tensorflow_core\python\eager\def_function.py", line 449, in __call__
    self._initialize(args, kwds, add_initializers_to=initializer_map)
  File "C:\ProgramData\Anaconda3\envs\keras\lib\site-packages\tensorflow_core\python\eager\def_function.py", line 392, in _initialize
    *args, **kwds))
  File "C:\ProgramData\Anaconda3\envs\keras\lib\site-packages\tensorflow_core\python\eager\function.py", line 1847, in _get_concrete_function_internal_garbage_collected
    graph_function, _, _ = self._maybe_define_function(args, kwargs)
  File "C:\ProgramData\Anaconda3\envs\keras\lib\site-packages\tensorflow_core\python\eager\function.py", line 2147, in _maybe_define_function
    graph_function = self._create_graph_function(args, kwargs)
  File "C:\ProgramData\Anaconda3\envs\keras\lib\site-packages\tensorflow_core\python\eager\function.py", line 2038, in _create_graph_function
    capture_by_value=self._capture_by_value),
  File "C:\ProgramData\Anaconda3\envs\keras\lib\site-packages\tensorflow_core\python\framework\func_graph.py", line 915, in func_graph_from_py_func
    func_outputs = python_func(*func_args, **func_kwargs)
  File "C:\ProgramData\Anaconda3\envs\keras\lib\site-packages\tensorflow_core\python\eager\def_function.py", line 335, in wrapped_fn
    return weak_wrapped_fn().__wrapped__(*args, **kwds)
  File "C:\ProgramData\Anaconda3\envs\keras\lib\site-packages\tensorflow_core\python\framework\func_graph.py", line 905, in wrapper
    raise e.ag_error_metadata.to_exception(e)
tensorflow.python.autograph.impl.api.StagingError: in converted code:

    C:\ProgramData\Anaconda3\envs\keras\lib\site-packages\tensorflow_core\python\framework\test_util.py:987 function_in_eager
        f(self, *args, **kwargs)
    jit_test.py:351 testDefunInheritsJitScope
        with jit.experimental_jit_scope(True):
    C:\ProgramData\Anaconda3\envs\keras\lib\contextlib.py:81 __enter__
        return next(self.gen)
    C:\ProgramData\Anaconda3\envs\keras\lib\site-packages\tensorflow_core\python\compiler\xla\jit.py:108 experimental_jit_scope
        xla_scope_counter = xla_scope_counter[0]

    IndexError: list index out of range


======================================================================
ERROR: testDefunInheritsJitScope_v1_graph (__main__.JITTest)
JITTest.testDefunInheritsJitScope_v1_graph
testDefunInheritsJitScope_v1_graph('v1_graph')
----------------------------------------------------------------------
Traceback (most recent call last):
  File "C:\ProgramData\Anaconda3\envs\keras\lib\site-packages\absl\testing\parameterized.py", line 284, in bound_param_test
    return test_method(self, *testcase_params)
  File "C:\ProgramData\Anaconda3\envs\keras\lib\site-packages\tensorflow_core\python\framework\test_util.py", line 982, in decorated
    f(self, *args, **kwargs)
  File "jit_test.py", line 351, in testDefunInheritsJitScope
    with jit.experimental_jit_scope(True):
  File "C:\ProgramData\Anaconda3\envs\keras\lib\contextlib.py", line 81, in __enter__
    return next(self.gen)
  File "C:\ProgramData\Anaconda3\envs\keras\lib\site-packages\tensorflow_core\python\compiler\xla\jit.py", line 108, in experimental_jit_scope
    xla_scope_counter = xla_scope_counter[0]
IndexError: list index out of range

======================================================================
ERROR: testJITCreateOpsLambda_function (__main__.JITTest)
JITTest.testJITCreateOpsLambda_function
testJITCreateOpsLambda_function('function')
----------------------------------------------------------------------
Traceback (most recent call last):
  File "C:\ProgramData\Anaconda3\envs\keras\lib\site-packages\absl\testing\parameterized.py", line 284, in bound_param_test
    return test_method(self, *testcase_params)
  File "C:\ProgramData\Anaconda3\envs\keras\lib\site-packages\tensorflow_core\python\framework\test_util.py", line 993, in decorated
    function_in_eager()
  File "C:\ProgramData\Anaconda3\envs\keras\lib\site-packages\tensorflow_core\python\eager\def_function.py", line 449, in __call__
    self._initialize(args, kwds, add_initializers_to=initializer_map)
  File "C:\ProgramData\Anaconda3\envs\keras\lib\site-packages\tensorflow_core\python\eager\def_function.py", line 392, in _initialize
    *args, **kwds))
  File "C:\ProgramData\Anaconda3\envs\keras\lib\site-packages\tensorflow_core\python\eager\function.py", line 1847, in _get_concrete_function_internal_garbage_collected
    graph_function, _, _ = self._maybe_define_function(args, kwargs)
  File "C:\ProgramData\Anaconda3\envs\keras\lib\site-packages\tensorflow_core\python\eager\function.py", line 2147, in _maybe_define_function
    graph_function = self._create_graph_function(args, kwargs)
  File "C:\ProgramData\Anaconda3\envs\keras\lib\site-packages\tensorflow_core\python\eager\function.py", line 2038, in _create_graph_function
    capture_by_value=self._capture_by_value),
  File "C:\ProgramData\Anaconda3\envs\keras\lib\site-packages\tensorflow_core\python\framework\func_graph.py", line 915, in func_graph_from_py_func
    func_outputs = python_func(*func_args, **func_kwargs)
  File "C:\ProgramData\Anaconda3\envs\keras\lib\site-packages\tensorflow_core\python\eager\def_function.py", line 335, in wrapped_fn
    return weak_wrapped_fn().__wrapped__(*args, **kwds)
  File "C:\ProgramData\Anaconda3\envs\keras\lib\site-packages\tensorflow_core\python\framework\func_graph.py", line 905, in wrapper
    raise e.ag_error_metadata.to_exception(e)
tensorflow.python.autograph.impl.api.StagingError: in converted code:

    C:\ProgramData\Anaconda3\envs\keras\lib\site-packages\tensorflow_core\python\framework\test_util.py:987 function_in_eager
        f(self, *args, **kwargs)
    jit_test.py:159 testJITCreateOpsLambda
        v_false_1_t, v_false_1 = self.compute(False, create_ops)
    jit_test.py:111 compute
        with jit.experimental_jit_scope(use_jit):
    C:\ProgramData\Anaconda3\envs\keras\lib\contextlib.py:81 __enter__
        return next(self.gen)
    C:\ProgramData\Anaconda3\envs\keras\lib\site-packages\tensorflow_core\python\compiler\xla\jit.py:108 experimental_jit_scope
        xla_scope_counter = xla_scope_counter[0]

    IndexError: list index out of range


======================================================================
ERROR: testJITCreateOpsLambda_v1_graph (__main__.JITTest)
JITTest.testJITCreateOpsLambda_v1_graph
testJITCreateOpsLambda_v1_graph('v1_graph')
----------------------------------------------------------------------
Traceback (most recent call last):
  File "C:\ProgramData\Anaconda3\envs\keras\lib\site-packages\absl\testing\parameterized.py", line 284, in bound_param_test
    return test_method(self, *testcase_params)
  File "C:\ProgramData\Anaconda3\envs\keras\lib\site-packages\tensorflow_core\python\framework\test_util.py", line 982, in decorated
    f(self, *args, **kwargs)
  File "jit_test.py", line 159, in testJITCreateOpsLambda
    v_false_1_t, v_false_1 = self.compute(False, create_ops)
  File "jit_test.py", line 111, in compute
    with jit.experimental_jit_scope(use_jit):
  File "C:\ProgramData\Anaconda3\envs\keras\lib\contextlib.py", line 81, in __enter__
    return next(self.gen)
  File "C:\ProgramData\Anaconda3\envs\keras\lib\site-packages\tensorflow_core\python\compiler\xla\jit.py", line 108, in experimental_jit_scope
    xla_scope_counter = xla_scope_counter[0]
IndexError: list index out of range

======================================================================
ERROR: testJITVariableSeed_function (__main__.JITTest)
JITTest.testJITVariableSeed_function
testJITVariableSeed_function('function')
----------------------------------------------------------------------
Traceback (most recent call last):
  File "C:\ProgramData\Anaconda3\envs\keras\lib\site-packages\absl\testing\parameterized.py", line 284, in bound_param_test
    return test_method(self, *testcase_params)
  File "C:\ProgramData\Anaconda3\envs\keras\lib\site-packages\tensorflow_core\python\framework\test_util.py", line 993, in decorated
    function_in_eager()
  File "C:\ProgramData\Anaconda3\envs\keras\lib\site-packages\tensorflow_core\python\eager\def_function.py", line 449, in __call__
    self._initialize(args, kwds, add_initializers_to=initializer_map)
  File "C:\ProgramData\Anaconda3\envs\keras\lib\site-packages\tensorflow_core\python\eager\def_function.py", line 392, in _initialize
    *args, **kwds))
  File "C:\ProgramData\Anaconda3\envs\keras\lib\site-packages\tensorflow_core\python\eager\function.py", line 1847, in _get_concrete_function_internal_garbage_collected
    graph_function, _, _ = self._maybe_define_function(args, kwargs)
  File "C:\ProgramData\Anaconda3\envs\keras\lib\site-packages\tensorflow_core\python\eager\function.py", line 2147, in _maybe_define_function
    graph_function = self._create_graph_function(args, kwargs)
  File "C:\ProgramData\Anaconda3\envs\keras\lib\site-packages\tensorflow_core\python\eager\function.py", line 2038, in _create_graph_function
    capture_by_value=self._capture_by_value),
  File "C:\ProgramData\Anaconda3\envs\keras\lib\site-packages\tensorflow_core\python\framework\func_graph.py", line 915, in func_graph_from_py_func
    func_outputs = python_func(*func_args, **func_kwargs)
  File "C:\ProgramData\Anaconda3\envs\keras\lib\site-packages\tensorflow_core\python\eager\def_function.py", line 335, in wrapped_fn
    return weak_wrapped_fn().__wrapped__(*args, **kwds)
  File "C:\ProgramData\Anaconda3\envs\keras\lib\site-packages\tensorflow_core\python\framework\func_graph.py", line 905, in wrapper
    raise e.ag_error_metadata.to_exception(e)
tensorflow.python.autograph.impl.api.StagingError: in converted code:

    C:\ProgramData\Anaconda3\envs\keras\lib\site-packages\tensorflow_core\python\framework\test_util.py:987 function_in_eager
        f(self, *args, **kwargs)
    jit_test.py:295 testJITVariableSeed
        _, v_false_1 = self.compute(False, create_ops)
    jit_test.py:111 compute
        with jit.experimental_jit_scope(use_jit):
    C:\ProgramData\Anaconda3\envs\keras\lib\contextlib.py:81 __enter__
        return next(self.gen)
    C:\ProgramData\Anaconda3\envs\keras\lib\site-packages\tensorflow_core\python\compiler\xla\jit.py:108 experimental_jit_scope
        xla_scope_counter = xla_scope_counter[0]

    IndexError: list index out of range


======================================================================
ERROR: testJITVariableSeed_v1_graph (__main__.JITTest)
JITTest.testJITVariableSeed_v1_graph
testJITVariableSeed_v1_graph('v1_graph')
----------------------------------------------------------------------
Traceback (most recent call last):
  File "C:\ProgramData\Anaconda3\envs\keras\lib\site-packages\absl\testing\parameterized.py", line 284, in bound_param_test
    return test_method(self, *testcase_params)
  File "C:\ProgramData\Anaconda3\envs\keras\lib\site-packages\tensorflow_core\python\framework\test_util.py", line 982, in decorated
    f(self, *args, **kwargs)
  File "jit_test.py", line 295, in testJITVariableSeed
    _, v_false_1 = self.compute(False, create_ops)
  File "jit_test.py", line 111, in compute
    with jit.experimental_jit_scope(use_jit):
  File "C:\ProgramData\Anaconda3\envs\keras\lib\contextlib.py", line 81, in __enter__
    return next(self.gen)
  File "C:\ProgramData\Anaconda3\envs\keras\lib\site-packages\tensorflow_core\python\compiler\xla\jit.py", line 108, in experimental_jit_scope
    xla_scope_counter = xla_scope_counter[0]
IndexError: list index out of range

======================================================================
ERROR: testJITXlaScope_function (__main__.JITTest)
JITTest.testJITXlaScope_function
testJITXlaScope_function('function')
----------------------------------------------------------------------
Traceback (most recent call last):
  File "C:\ProgramData\Anaconda3\envs\keras\lib\site-packages\absl\testing\parameterized.py", line 284, in bound_param_test
    return test_method(self, *testcase_params)
  File "C:\ProgramData\Anaconda3\envs\keras\lib\site-packages\tensorflow_core\python\framework\test_util.py", line 993, in decorated
    function_in_eager()
  File "C:\ProgramData\Anaconda3\envs\keras\lib\site-packages\tensorflow_core\python\eager\def_function.py", line 449, in __call__
    self._initialize(args, kwds, add_initializers_to=initializer_map)
  File "C:\ProgramData\Anaconda3\envs\keras\lib\site-packages\tensorflow_core\python\eager\def_function.py", line 392, in _initialize
    *args, **kwds))
  File "C:\ProgramData\Anaconda3\envs\keras\lib\site-packages\tensorflow_core\python\eager\function.py", line 1847, in _get_concrete_function_internal_garbage_collected
    graph_function, _, _ = self._maybe_define_function(args, kwargs)
  File "C:\ProgramData\Anaconda3\envs\keras\lib\site-packages\tensorflow_core\python\eager\function.py", line 2147, in _maybe_define_function
    graph_function = self._create_graph_function(args, kwargs)
  File "C:\ProgramData\Anaconda3\envs\keras\lib\site-packages\tensorflow_core\python\eager\function.py", line 2038, in _create_graph_function
    capture_by_value=self._capture_by_value),
  File "C:\ProgramData\Anaconda3\envs\keras\lib\site-packages\tensorflow_core\python\framework\func_graph.py", line 915, in func_graph_from_py_func
    func_outputs = python_func(*func_args, **func_kwargs)
  File "C:\ProgramData\Anaconda3\envs\keras\lib\site-packages\tensorflow_core\python\eager\def_function.py", line 335, in wrapped_fn
    return weak_wrapped_fn().__wrapped__(*args, **kwds)
  File "C:\ProgramData\Anaconda3\envs\keras\lib\site-packages\tensorflow_core\python\framework\func_graph.py", line 905, in wrapper
    raise e.ag_error_metadata.to_exception(e)
tensorflow.python.autograph.impl.api.StagingError: in converted code:

    C:\ProgramData\Anaconda3\envs\keras\lib\site-packages\tensorflow_core\python\framework\test_util.py:987 function_in_eager
        f(self, *args, **kwargs)
    jit_test.py:213 testJITXlaScope
        with jit.experimental_jit_scope(True):
    C:\ProgramData\Anaconda3\envs\keras\lib\contextlib.py:81 __enter__
        return next(self.gen)
    C:\ProgramData\Anaconda3\envs\keras\lib\site-packages\tensorflow_core\python\compiler\xla\jit.py:108 experimental_jit_scope
        xla_scope_counter = xla_scope_counter[0]

    IndexError: list index out of range


======================================================================
ERROR: testJITXlaScope_v1_graph (__main__.JITTest)
JITTest.testJITXlaScope_v1_graph
testJITXlaScope_v1_graph('v1_graph')
----------------------------------------------------------------------
Traceback (most recent call last):
  File "C:\ProgramData\Anaconda3\envs\keras\lib\site-packages\absl\testing\parameterized.py", line 284, in bound_param_test
    return test_method(self, *testcase_params)
  File "C:\ProgramData\Anaconda3\envs\keras\lib\site-packages\tensorflow_core\python\framework\test_util.py", line 982, in decorated
    f(self, *args, **kwargs)
  File "jit_test.py", line 213, in testJITXlaScope
    with jit.experimental_jit_scope(True):
  File "C:\ProgramData\Anaconda3\envs\keras\lib\contextlib.py", line 81, in __enter__
    return next(self.gen)
  File "C:\ProgramData\Anaconda3\envs\keras\lib\site-packages\tensorflow_core\python\compiler\xla\jit.py", line 108, in experimental_jit_scope
    xla_scope_counter = xla_scope_counter[0]
IndexError: list index out of range

----------------------------------------------------------------------
Ran 23 tests in 2.816s

FAILED (errors=18, skipped=3)
