2020-10-04 14:46:32.652495: I tensorflow/stream_executor/platform/default/dso_loader.cc:44] Successfully opened dynamic library cudart64_100.dll
============================= test session starts =============================
platform win32 -- Python 3.6.12, pytest-6.0.2, py-1.9.0, pluggy-0.13.1
rootdir: C:\Users\mutation\Desktop\testcase\tests\keras\engine
plugins: flaky-3.7.0
collected 34 items

test_training.py ....F..s..........................                      [100%]

================================== FAILURES ===================================
_____________________________ test_fit_generator ______________________________

    @flaky(rerun_filter=lambda err, *args: issubclass(err[0], AssertionError))
    def test_fit_generator():
        model = get_model(num_outputs=2)
        optimizer = 'rmsprop'
        loss = 'mse'
        loss_weights = [1., 0.5]
    
        model.compile(optimizer, loss, metrics=[], loss_weights=loss_weights,
                      sample_weight_mode=None)
        tracker_cb = TrackerCallback()
        val_seq = RandomSequence(4)
        out = model.fit_generator(generator=RandomSequence(3),
                                  steps_per_epoch=3,
                                  epochs=5,
                                  initial_epoch=0,
                                  validation_data=val_seq,
                                  validation_steps=3,
                                  max_queue_size=1,
                                  callbacks=[tracker_cb])
>       assert tracker_cb.trained_epochs == [0, 1, 2, 3, 4]
E       assert [0] == [0, 1, 2, 3, 4]
E         Right contains 4 more items, first extra item: 1
E         Use -v to get the full diff

test_training.py:491: AssertionError
---------------------------- Captured stdout call -----------------------------
Epoch 1/5

1/3 [=========>....................] - ETA: 0s - loss: 1.1278 - dense_1_loss: 1.0062 - dropout_loss: 0.2433
3/3 [==============================] - 0s 42ms/step - loss: 0.9599 - dense_1_loss: 0.7688 - dropout_loss: 0.3822 - val_loss: 0.6109 - val_dense_1_loss: 0.7034 - val_dropout_loss: 0.1710
---------------------------- Captured stderr call -----------------------------
2020-10-04 14:46:42.210480: I tensorflow/core/common_runtime/gpu/gpu_device.cc:1618] Found device 0 with properties: 
name: GeForce RTX 2080 Ti major: 7 minor: 5 memoryClockRate(GHz): 1.65
pciBusID: 0000:73:00.0
2020-10-04 14:46:42.211065: I tensorflow/stream_executor/platform/default/dso_loader.cc:44] Successfully opened dynamic library cudart64_100.dll
2020-10-04 14:46:42.211414: I tensorflow/stream_executor/platform/default/dso_loader.cc:44] Successfully opened dynamic library cublas64_100.dll
2020-10-04 14:46:42.211755: I tensorflow/stream_executor/platform/default/dso_loader.cc:44] Successfully opened dynamic library cufft64_100.dll
2020-10-04 14:46:42.212097: I tensorflow/stream_executor/platform/default/dso_loader.cc:44] Successfully opened dynamic library curand64_100.dll
2020-10-04 14:46:42.212437: I tensorflow/stream_executor/platform/default/dso_loader.cc:44] Successfully opened dynamic library cusolver64_100.dll
2020-10-04 14:46:42.212790: I tensorflow/stream_executor/platform/default/dso_loader.cc:44] Successfully opened dynamic library cusparse64_100.dll
2020-10-04 14:46:42.213140: I tensorflow/stream_executor/platform/default/dso_loader.cc:44] Successfully opened dynamic library cudnn64_7.dll
2020-10-04 14:46:42.213708: I tensorflow/core/common_runtime/gpu/gpu_device.cc:1746] Adding visible gpu devices: 0
2020-10-04 14:46:42.214023: I tensorflow/core/common_runtime/gpu/gpu_device.cc:1159] Device interconnect StreamExecutor with strength 1 edge matrix:
2020-10-04 14:46:42.214373: I tensorflow/core/common_runtime/gpu/gpu_device.cc:1165]      0 
2020-10-04 14:46:42.214592: I tensorflow/core/common_runtime/gpu/gpu_device.cc:1178] 0:   N 
2020-10-04 14:46:42.215091: I tensorflow/core/common_runtime/gpu/gpu_device.cc:1304] Created TensorFlow device (/job:localhost/replica:0/task:0/device:GPU:0 with 8686 MB memory) -> physical GPU (device: 0, name: GeForce RTX 2080 Ti, pci bus id: 0000:73:00.0, compute capability: 7.5)
---------------------------- Captured stdout call -----------------------------
Epoch 1/5

1/3 [=========>....................] - ETA: 0s - loss: 1.1553 - dense_1_loss: 0.8552 - dropout_loss: 0.6002
3/3 [==============================] - 0s 47ms/step - loss: 1.0195 - dense_1_loss: 0.7410 - dropout_loss: 0.5571 - val_loss: 0.4815 - val_dense_1_loss: 0.4673 - val_dropout_loss: 0.1696
---------------------------- Captured stderr call -----------------------------
2020-10-04 14:46:44.021528: I tensorflow/core/common_runtime/gpu/gpu_device.cc:1618] Found device 0 with properties: 
name: GeForce RTX 2080 Ti major: 7 minor: 5 memoryClockRate(GHz): 1.65
pciBusID: 0000:73:00.0
2020-10-04 14:46:44.022131: I tensorflow/stream_executor/platform/default/dso_loader.cc:44] Successfully opened dynamic library cudart64_100.dll
2020-10-04 14:46:44.022480: I tensorflow/stream_executor/platform/default/dso_loader.cc:44] Successfully opened dynamic library cublas64_100.dll
2020-10-04 14:46:44.022824: I tensorflow/stream_executor/platform/default/dso_loader.cc:44] Successfully opened dynamic library cufft64_100.dll
2020-10-04 14:46:44.023161: I tensorflow/stream_executor/platform/default/dso_loader.cc:44] Successfully opened dynamic library curand64_100.dll
2020-10-04 14:46:44.023503: I tensorflow/stream_executor/platform/default/dso_loader.cc:44] Successfully opened dynamic library cusolver64_100.dll
2020-10-04 14:46:44.023861: I tensorflow/stream_executor/platform/default/dso_loader.cc:44] Successfully opened dynamic library cusparse64_100.dll
2020-10-04 14:46:44.024205: I tensorflow/stream_executor/platform/default/dso_loader.cc:44] Successfully opened dynamic library cudnn64_7.dll
2020-10-04 14:46:44.024766: I tensorflow/core/common_runtime/gpu/gpu_device.cc:1746] Adding visible gpu devices: 0
2020-10-04 14:46:44.025079: I tensorflow/core/common_runtime/gpu/gpu_device.cc:1159] Device interconnect StreamExecutor with strength 1 edge matrix:
2020-10-04 14:46:44.025426: I tensorflow/core/common_runtime/gpu/gpu_device.cc:1165]      0 
2020-10-04 14:46:44.025643: I tensorflow/core/common_runtime/gpu/gpu_device.cc:1178] 0:   N 
2020-10-04 14:46:44.026133: I tensorflow/core/common_runtime/gpu/gpu_device.cc:1304] Created TensorFlow device (/job:localhost/replica:0/task:0/device:GPU:0 with 8686 MB memory) -> physical GPU (device: 0, name: GeForce RTX 2080 Ti, pci bus id: 0000:73:00.0, compute capability: 7.5)
============================== warnings summary ===============================
C:\ProgramData\Anaconda3\envs\keras\lib\site-packages\_pytest\config\__init__.py:1040
  C:\ProgramData\Anaconda3\envs\keras\lib\site-packages\_pytest\config\__init__.py:1040: PytestAssertRewriteWarning: Module already imported so cannot be rewritten: flaky
    self._mark_plugins_for_rewrite(hook)

test_training.py::test_model_methods
test_training.py::test_model_with_partial_loss
test_training.py::test_model_with_external_loss
  C:\ProgramData\Anaconda3\envs\keras\lib\site-packages\keras\engine\training_utils.py:819: UserWarning: Output dense_1 missing from loss dictionary. We assume this was done on purpose. The fit and evaluate APIs will not be expecting any data to be passed to dense_1.
    'be expecting any data to be passed to {0}.'.format(name))

test_training.py::test_model_methods
test_training.py::test_model_with_external_loss
  C:\ProgramData\Anaconda3\envs\keras\lib\site-packages\keras\engine\training_utils.py:819: UserWarning: Output dropout missing from loss dictionary. We assume this was done on purpose. The fit and evaluate APIs will not be expecting any data to be passed to dropout.
    'be expecting any data to be passed to {0}.'.format(name))

test_training.py::test_model_with_external_loss
  C:\ProgramData\Anaconda3\envs\keras\lib\site-packages\keras\engine\training_utils.py:819: UserWarning: Output dense_2 missing from loss dictionary. We assume this was done on purpose. The fit and evaluate APIs will not be expecting any data to be passed to dense_2.
    'be expecting any data to be passed to {0}.'.format(name))

-- Docs: https://docs.pytest.org/en/stable/warnings.html
===Flaky Test Report===

test_model_methods passed 1 out of the required 1 times. Success!
test_fit_generator failed (1 runs remaining out of 2).
	<class 'AssertionError'>
	assert [0] == [0, 1, 2, 3, 4]
  Right contains 4 more items, first extra item: 1
  Use -v to get the full diff
	[<TracebackEntry C:\Users\mutation\Desktop\testcase\tests\keras\engine\test_training.py:491>]
test_fit_generator failed; it passed 0 out of the required 1 times.
	<class 'AssertionError'>
	assert [0] == [0, 1, 2, 3, 4]
  Right contains 4 more items, first extra item: 1
  Use -v to get the full diff
	[<TracebackEntry C:\Users\mutation\Desktop\testcase\tests\keras\engine\test_training.py:491>]

===End Flaky Test Report===
=========================== short test summary info ===========================
FAILED test_training.py::test_fit_generator - assert [0] == [0, 1, 2, 3, 4]
============ 1 failed, 32 passed, 1 skipped, 7 warnings in 27.05s =============
