........F.
======================================================================
FAIL: test_in_update_shared (test_function.TestFunctionIn)
----------------------------------------------------------------------
Traceback (most recent call last):
  File "C:\Users\mutation\Desktop\theano-testcase\tests\test_function.py", line 118, in test_in_update_shared
    assert np.allclose(shared_var.get_value(), i % 2)
AssertionError

----------------------------------------------------------------------
Ran 10 tests in 4.214s

FAILED (failures=1)
