2020-10-03 17:15:57.779419: I tensorflow/stream_executor/platform/default/dso_loader.cc:44] Successfully opened dynamic library cudart64_100.dll
============================= test session starts =============================
platform win32 -- Python 3.6.12, pytest-6.0.2, py-1.9.0, pluggy-0.13.1
rootdir: C:\Users\mutation\Desktop\testcase\tests\keras\layers
plugins: flaky-3.7.0
collected 110 items

convolutional_test.py ......................F........................... [ 45%]
............................................................             [100%]

================================== FAILURES ===================================
____________________ test_conv2d_transpose_channels_first _____________________

    def test_conv2d_transpose_channels_first():
        num_samples = 2
        filters = 2
        stack_size = 3
        num_row = 5
        num_col = 6
        padding = 'valid'
        strides = (2, 2)
    
        layer_test(convolutional.Conv2DTranspose,
                   kwargs={'filters': filters,
                           'kernel_size': 3,
                           'padding': padding,
                           'data_format': 'channels_first',
                           'activation': None,
                           'kernel_regularizer': 'l2',
                           'bias_regularizer': 'l2',
                           'activity_regularizer': 'l2',
                           'kernel_constraint': 'max_norm',
                           'bias_constraint': 'max_norm',
                           'strides': strides},
                   input_shape=(num_samples, stack_size, num_row, num_col),
>                  fixed_batch_size=True)

convolutional_test.py:268: 
_ _ _ _ _ _ _ _ _ _ _ _ _ _ _ _ _ _ _ _ _ _ _ _ _ _ _ _ _ _ _ _ _ _ _ _ _ _ _ _
C:\ProgramData\Anaconda3\envs\keras\lib\site-packages\keras\utils\test_utils.py:100: in layer_test
    actual_output = model.predict(input_data)
C:\ProgramData\Anaconda3\envs\keras\lib\site-packages\keras\engine\training.py:1462: in predict
    callbacks=callbacks)
C:\ProgramData\Anaconda3\envs\keras\lib\site-packages\keras\engine\training_arrays.py:324: in predict_loop
    batch_outs = f(ins_batch)
C:\ProgramData\Anaconda3\envs\keras\lib\site-packages\tensorflow_core\python\keras\backend.py:3476: in __call__
    run_metadata=self.run_metadata)
_ _ _ _ _ _ _ _ _ _ _ _ _ _ _ _ _ _ _ _ _ _ _ _ _ _ _ _ _ _ _ _ _ _ _ _ _ _ _ _

self = <tensorflow.python.client.session.BaseSession._Callable object at 0x00000244E05F6FD0>
args = (array([[[[5.4241986 , 4.6218467 , 7.244986  , 8.903816  , 0.36628655,
          9.964992  ],
         [2.8343527 , 6....635 ],
         [1.5581794 , 0.33720896, 8.284694  , 9.934791  , 6.200072  ,
          3.7914586 ]]]], dtype=float32),)
kwargs = {'run_metadata': None}, run_metadata = None, run_metadata_ptr = None

    def __call__(self, *args, **kwargs):
      # TODO(b/74355905): Support argument and return value nested structures,
      # and tensor-like objects such as SparseTensors.
      run_metadata = kwargs.get('run_metadata', None)
      try:
        run_metadata_ptr = tf_session.TF_NewBuffer() if run_metadata else None
        ret = tf_session.TF_SessionRunCallable(self._session._session,
                                               self._handle, args,
>                                              run_metadata_ptr)
E                                              tensorflow.python.framework.errors_impl.InvalidArgumentError: 2 root error(s) found.
E                                                (0) Invalid argument: Conv2DSlowBackpropInput: filter and out_backprop must have the same out_depth
E                                              	 [[{{node conv2d_transpose_1/conv2d_transpose}}]]
E                                                (1) Invalid argument: Conv2DSlowBackpropInput: filter and out_backprop must have the same out_depth
E                                              	 [[{{node conv2d_transpose_1/conv2d_transpose}}]]
E                                              	 [[conv2d_transpose_1/BiasAdd/_7]]
E                                              0 successful operations.
E                                              0 derived errors ignored.

C:\ProgramData\Anaconda3\envs\keras\lib\site-packages\tensorflow_core\python\client\session.py:1472: InvalidArgumentError
---------------------------- Captured stderr call -----------------------------
2020-10-03 17:16:10.506641: I tensorflow/core/common_runtime/gpu/gpu_device.cc:1618] Found device 0 with properties: 
name: GeForce RTX 2080 Ti major: 7 minor: 5 memoryClockRate(GHz): 1.65
pciBusID: 0000:73:00.0
2020-10-03 17:16:10.507233: I tensorflow/stream_executor/platform/default/dso_loader.cc:44] Successfully opened dynamic library cudart64_100.dll
2020-10-03 17:16:10.507576: I tensorflow/stream_executor/platform/default/dso_loader.cc:44] Successfully opened dynamic library cublas64_100.dll
2020-10-03 17:16:10.507917: I tensorflow/stream_executor/platform/default/dso_loader.cc:44] Successfully opened dynamic library cufft64_100.dll
2020-10-03 17:16:10.508253: I tensorflow/stream_executor/platform/default/dso_loader.cc:44] Successfully opened dynamic library curand64_100.dll
2020-10-03 17:16:10.508593: I tensorflow/stream_executor/platform/default/dso_loader.cc:44] Successfully opened dynamic library cusolver64_100.dll
2020-10-03 17:16:10.508935: I tensorflow/stream_executor/platform/default/dso_loader.cc:44] Successfully opened dynamic library cusparse64_100.dll
2020-10-03 17:16:10.509353: I tensorflow/stream_executor/platform/default/dso_loader.cc:44] Successfully opened dynamic library cudnn64_7.dll
2020-10-03 17:16:10.510066: I tensorflow/core/common_runtime/gpu/gpu_device.cc:1746] Adding visible gpu devices: 0
2020-10-03 17:16:10.510455: I tensorflow/core/common_runtime/gpu/gpu_device.cc:1159] Device interconnect StreamExecutor with strength 1 edge matrix:
2020-10-03 17:16:10.510826: I tensorflow/core/common_runtime/gpu/gpu_device.cc:1165]      0 
2020-10-03 17:16:10.511045: I tensorflow/core/common_runtime/gpu/gpu_device.cc:1178] 0:   N 
2020-10-03 17:16:10.511591: I tensorflow/core/common_runtime/gpu/gpu_device.cc:1304] Created TensorFlow device (/job:localhost/replica:0/task:0/device:GPU:0 with 8686 MB memory) -> physical GPU (device: 0, name: GeForce RTX 2080 Ti, pci bus id: 0000:73:00.0, compute capability: 7.5)
2020-10-03 17:16:10.532687: W tensorflow/core/framework/op_kernel.cc:1651] OP_REQUIRES failed at conv_grad_input_ops.cc:811 : Invalid argument: Conv2DSlowBackpropInput: filter and out_backprop must have the same out_depth
=========================== short test summary info ===========================
FAILED convolutional_test.py::test_conv2d_transpose_channels_first - tensorfl...
======================= 1 failed, 109 passed in 27.93s ========================
