2020-10-04 14:48:17.374309: I tensorflow/stream_executor/platform/default/dso_loader.cc:44] Successfully opened dynamic library cudart64_100.dll
============================= test session starts =============================
platform win32 -- Python 3.6.12, pytest-6.0.2, py-1.9.0, pluggy-0.13.1
rootdir: C:\Users\mutation\Desktop\testcase\tests\keras\engine
plugins: flaky-3.7.0
collected 34 items

test_training.py .....F.s..........................                      [100%]

================================== FAILURES ===================================
__________________________ test_fit_generator_shape ___________________________

    def test_fit_generator_shape():
        # predict_generator output shape behavior should be consistent
        def expected_shape(batch_size, n_batches):
            return (batch_size * n_batches, 4), (batch_size * n_batches, 3)
    
        model = get_model(num_outputs=2)
        optimizer = 'rmsprop'
        loss = 'mse'
    
        # Multiple outputs and one step.
        batch_size = 5
        sequence_length = 1
        shape_0, shape_1 = expected_shape(batch_size, sequence_length)
        out = model.predict_generator(
>           RandomSequence(batch_size, sequence_length=sequence_length))

test_training.py:623: 
_ _ _ _ _ _ _ _ _ _ _ _ _ _ _ _ _ _ _ _ _ _ _ _ _ _ _ _ _ _ _ _ _ _ _ _ _ _ _ _
C:\ProgramData\Anaconda3\envs\keras\lib\site-packages\keras\legacy\interfaces.py:91: in wrapper
    return func(*args, **kwargs)
C:\ProgramData\Anaconda3\envs\keras\lib\site-packages\keras\engine\training.py:1846: in predict_generator
    verbose=verbose)
_ _ _ _ _ _ _ _ _ _ _ _ _ _ _ _ _ _ _ _ _ _ _ _ _ _ _ _ _ _ _ _ _ _ _ _ _ _ _ _

model = <keras.engine.training.Model object at 0x0000029C283A3080>
generator = <test_training.RandomSequence object at 0x0000029C283AFBE0>
steps = None
callbacks = <keras.callbacks.callbacks.CallbackList object at 0x0000029C283D04E0>
max_queue_size = 10, workers = 1, use_multiprocessing = False, verbose = 0

    def predict_generator(model, generator,
                          steps=None,
                          callbacks=None,
                          max_queue_size=10,
                          workers=1,
                          use_multiprocessing=False,
                          verbose=0):
        """See docstring for `Model.predict_generator`."""
        model._make_predict_function()
    
        steps_done = 0
        all_outs = []
        use_sequence_api = is_sequence(generator)
        if not use_sequence_api and use_multiprocessing and workers > 1:
            warnings.warn(
                UserWarning('Using a generator with `use_multiprocessing=True`'
                            ' and multiple workers may duplicate your data.'
                            ' Please consider using the `keras.utils.Sequence'
                            ' class.'))
        if steps is not None:
            if use_sequence_api:
                steps = len(generator)
            else:
                raise ValueError('`steps=None` is only valid for a generator'
                                 ' based on the `keras.utils.Sequence` class.'
                                 ' Please specify `steps` or use the'
                                 ' `keras.utils.Sequence` class.')
        enqueuer = None
    
        # Check if callbacks have not been already configured
        if not isinstance(callbacks, cbks.CallbackList):
            callbacks = cbks.CallbackList(callbacks)
            callback_model = model._get_callback_model()
            callbacks.set_model(callback_model)
            callback_params = {
                'steps': steps,
                'verbose': verbose,
            }
            callbacks.set_params(callback_params)
    
        callbacks.model.stop_training = False
        callbacks._call_begin_hook('predict')
    
        try:
            if workers > 0:
                if use_sequence_api:
                    enqueuer = OrderedEnqueuer(
                        generator,
                        use_multiprocessing=use_multiprocessing)
                else:
                    enqueuer = GeneratorEnqueuer(
                        generator,
                        use_multiprocessing=use_multiprocessing)
                enqueuer.start(workers=workers, max_queue_size=max_queue_size)
                output_generator = enqueuer.get()
            else:
                if use_sequence_api:
                    output_generator = iter_sequence_infinite(generator)
                else:
                    output_generator = generator
    
            if verbose == 1:
                progbar = Progbar(target=steps)
    
>           while steps_done < steps:
E           TypeError: '<' not supported between instances of 'int' and 'NoneType'

C:\ProgramData\Anaconda3\envs\keras\lib\site-packages\keras\engine\training_generator.py:490: TypeError
---------------------------- Captured stderr call -----------------------------
2020-10-04 14:48:31.138223: I tensorflow/core/common_runtime/gpu/gpu_device.cc:1618] Found device 0 with properties: 
name: GeForce RTX 2080 Ti major: 7 minor: 5 memoryClockRate(GHz): 1.65
pciBusID: 0000:73:00.0
2020-10-04 14:48:31.138828: I tensorflow/stream_executor/platform/default/dso_loader.cc:44] Successfully opened dynamic library cudart64_100.dll
2020-10-04 14:48:31.139180: I tensorflow/stream_executor/platform/default/dso_loader.cc:44] Successfully opened dynamic library cublas64_100.dll
2020-10-04 14:48:31.139530: I tensorflow/stream_executor/platform/default/dso_loader.cc:44] Successfully opened dynamic library cufft64_100.dll
2020-10-04 14:48:31.139871: I tensorflow/stream_executor/platform/default/dso_loader.cc:44] Successfully opened dynamic library curand64_100.dll
2020-10-04 14:48:31.140217: I tensorflow/stream_executor/platform/default/dso_loader.cc:44] Successfully opened dynamic library cusolver64_100.dll
2020-10-04 14:48:31.140564: I tensorflow/stream_executor/platform/default/dso_loader.cc:44] Successfully opened dynamic library cusparse64_100.dll
2020-10-04 14:48:31.140921: I tensorflow/stream_executor/platform/default/dso_loader.cc:44] Successfully opened dynamic library cudnn64_7.dll
2020-10-04 14:48:31.141512: I tensorflow/core/common_runtime/gpu/gpu_device.cc:1746] Adding visible gpu devices: 0
2020-10-04 14:48:31.141831: I tensorflow/core/common_runtime/gpu/gpu_device.cc:1159] Device interconnect StreamExecutor with strength 1 edge matrix:
2020-10-04 14:48:31.142184: I tensorflow/core/common_runtime/gpu/gpu_device.cc:1165]      0 
2020-10-04 14:48:31.142403: I tensorflow/core/common_runtime/gpu/gpu_device.cc:1178] 0:   N 
2020-10-04 14:48:31.142924: I tensorflow/core/common_runtime/gpu/gpu_device.cc:1304] Created TensorFlow device (/job:localhost/replica:0/task:0/device:GPU:0 with 8686 MB memory) -> physical GPU (device: 0, name: GeForce RTX 2080 Ti, pci bus id: 0000:73:00.0, compute capability: 7.5)
============================== warnings summary ===============================
C:\ProgramData\Anaconda3\envs\keras\lib\site-packages\_pytest\config\__init__.py:1040
  C:\ProgramData\Anaconda3\envs\keras\lib\site-packages\_pytest\config\__init__.py:1040: PytestAssertRewriteWarning: Module already imported so cannot be rewritten: flaky
    self._mark_plugins_for_rewrite(hook)

test_training.py::test_model_methods
test_training.py::test_model_with_partial_loss
test_training.py::test_model_with_external_loss
  C:\ProgramData\Anaconda3\envs\keras\lib\site-packages\keras\engine\training_utils.py:819: UserWarning: Output dense_1 missing from loss dictionary. We assume this was done on purpose. The fit and evaluate APIs will not be expecting any data to be passed to dense_1.
    'be expecting any data to be passed to {0}.'.format(name))

test_training.py::test_model_methods
test_training.py::test_model_with_external_loss
  C:\ProgramData\Anaconda3\envs\keras\lib\site-packages\keras\engine\training_utils.py:819: UserWarning: Output dropout missing from loss dictionary. We assume this was done on purpose. The fit and evaluate APIs will not be expecting any data to be passed to dropout.
    'be expecting any data to be passed to {0}.'.format(name))

test_training.py::test_model_with_external_loss
  C:\ProgramData\Anaconda3\envs\keras\lib\site-packages\keras\engine\training_utils.py:819: UserWarning: Output dense_2 missing from loss dictionary. We assume this was done on purpose. The fit and evaluate APIs will not be expecting any data to be passed to dense_2.
    'be expecting any data to be passed to {0}.'.format(name))

-- Docs: https://docs.pytest.org/en/stable/warnings.html
===Flaky Test Report===

test_model_methods passed 1 out of the required 1 times. Success!
test_fit_generator passed 1 out of the required 1 times. Success!

===End Flaky Test Report===
=========================== short test summary info ===========================
FAILED test_training.py::test_fit_generator_shape - TypeError: '<' not suppor...
============ 1 failed, 32 passed, 1 skipped, 7 warnings in 29.89s =============
